Workbook

Sheet CSO Rates
A1: CSO | B1: AM | C1: AE | D1: 41 | E1: 58 | F1: 58CET | G1: 58CET | H1: 80 | I1: 80 | J1: 80 | K1: 80 | L1: 80 | M1: 80 | N1: 80B | O1: 80B | P1: 80B
A2: Sex | B2: M | C2: M | D2: M | E2: M | F2: M | G2: F | H2: M | I2: M | J2: F | K2: F | L2: U | M2: U | N2: M | O2: F | P2: U
A3: UW | B3: X | C3: X | D3: X | E3: X | F3: X | G3: X | H3: S | I3: N | J3: S | K3: N | L3: S | M3: N | N3: B | O3: B | P3: B
B4: =_xlfn.CONCAT(B1,B2,B3) -> AMMX | C4: =_xlfn.CONCAT(C1,C2,C3) -> AEMX | D4: =_xlfn.CONCAT(D1,D2,D3) -> 41MX | E4: =_xlfn.CONCAT(E1,E2,E3) -> 58MX | F4: =_xlfn.CONCAT(F1,F2,F3) -> 58CETMX | G4: =_xlfn.CONCAT(G1,G2,G3) -> 58CETFX | H4: =_xlfn.CONCAT(H1,H2,H3) -> 80MS | I4: =_xlfn.CONCAT(I1,I2,I3) -> 80MN | ... P4: =_xlfn.CONCAT(P1,P2,P3) -> 80BUB
A5: 0 | B5: 0.11246 | C5: 0.154701 | D5: 0.02258 | E5: 0.00708 | F5: 0.00783 | G5: 0.00695 | H5: 0.00107 | I5: 0.00107 | J5: 0.00087 | K5: 0.00087 | L5: 0.00392 | M5: 0.00392 | N5: 0.00418 | O5: 0.00289 | P5: 0.00392
A6: 1 | B6: 0.02639 | C6: 0.063494 | D6: 0.00577 | E6: 0.00176 | F6: 0.00251 | G6: 0.00242 | H6: 0.00107 | I6: 0.00107 | J6: 0.00087 | K6: 0.00087 | L6: 0.00104 | M6: 0.00104 | N6: 0.00107 | O6: 0.00087 | P6: 0.00104
A7: 2 | B7: 0.01187 | C7: 0.035503 | D7: 0.00414 | E7: 0.00152 | F7: 0.00227 | G7: 0.00216 | H7: 0.00099 | I7: 0.00099 | J7: 0.00081 | K7: 0.00081 | L7: 0.00095 | M7: 0.00095 | N7: 0.00099 | O7: 0.00081 | P7: 0.00095
A8: 3 | B8: 0.00709 | C8: 0.023905 | D8: 0.00338 | E8: 0.00146 | F8: 0.00221 | G8: 0.0021 | H8: 0.00098 | I8: 0.00098 | J8: 0.00079 | K8: 0.00079 | L8: 0.00094 | M8: 0.00094 | N8: 0.00098 | O8: 0.00079 | P8: 0.00094
A9: 4 | B9: 0.00491 | C9: 0.017699 | D9: 0.00299 | E9: 0.0014 | F9: 0.00215 | G9: 0.00204 | H9: 0.00095 | I9: 0.00095 | J9: 0.00077 | K9: 0.00077 | L9: 0.00091 | M9: 0.00091 | N9: 0.00095 | O9: 0.00077 | P9: 0.00091
A10: 5 | B10: 0.00394 | C10: 0.013601 | D10: 0.00276 | E10: 0.00135 | F10: 0.0021 | G10: 0.00199 | H10: 0.0009 | I10: 0.0009 | J10: 0.00076 | K10: 0.00076 | L10: 0.00087 | M10: 0.00087 | N10: 0.0009 | O10: 0.00076 | P10: 0.00087
A11: 6 | B11: 0.00338 | C11: 0.011372 | D11: 0.00261 | E11: 0.0013 | F11: 0.00205 | G11: 0.00194 | H11: 0.00086 | I11: 0.00086 | J11: 0.00073 | K11: 0.00073 | L11: 0.00083 | M11: 0.00083 | N11: 0.00086 | O11: 0.00073 | P11: 0.00083
A12: 7 | B12: 0.00305 | C12: 0.009749 | D12: 0.00247 | E12: 0.00126 | F12: 0.00201 | G12: 0.0019 | H12: 0.0008 | I12: 0.0008 | J12: 0.00072 | K12: 0.00072 | L12: 0.00079 | M12: 0.00079 | N12: 0.0008 | O12: 0.00072 | P12: 0.00079
A13: 8 | B13: 0.00293 | C13: 0.008626 | D13: 0.00231 | E13: 0.00123 | F13: 0.00198 | G13: 0.00187 | H13: 0.00076 | I13: 0.00076 | J13: 0.0007 | K13: 0.0007 | L13: 0.00075 | M13: 0.00075 | N13: 0.00076 | O13: 0.0007 | P13: 0.00075
A14: 9 | B14: 0.00296 | C14: 0.007897 | D14: 0.00212 | E14: 0.00121 | F14: 0.00196 | G14: 0.00186 | H14: 0.00074 | I14: 0.00074 | J14: 0.00069 | K14: 0.00069 | L14: 0.00073 | M14: 0.00073 | N14: 0.00074 | O14: 0.00069 | P14: 0.00073
A15: 10 | B15: 0.00307 | C15: 0.00749 | D15: 0.00197 | E15: 0.00121 | F15: 0.00196 | G15: 0.00186 | H15: 0.00073 | I15: 0.00073 | J15: 0.00068 | K15: 0.00068 | L15: 0.00072 | M15: 0.00072 | N15: 0.00073 | O15: 0.00068 | P15: 0.00072
A16: 11 | B16: 0.00317 | C16: 0.007516 | D16: 0.00191 | E16: 0.00123 | F16: 0.00198 | G16: 0.00187 | H16: 0.00077 | I16: 0.00077 | J16: 0.00069 | K16: 0.00069 | L16: 0.00075 | M16: 0.00075 | N16: 0.00077 | O16: 0.00069 | P16: 0.00075
... A100: 95 | B100: 0.38776 | C100: 1 | D100: 0.39621 | E100: 0.35124 | F100: 0.45661 | G100: 0.34571 | H100: 0.32996 | I100: 0.32996 | J100: 0.31732 | K100: 0.31732 | L100: 0.32489 | M100: 0.32489 | N100: 0.32996 | O100: 0.31732 | P100: 0.32489
A101: 96 | B101: 0.41111 | D101: 0.44719 | E101: 0.40056 | F101: 0.52073 | G101: 0.37609 | H101: 0.38455 | I101: 0.38455 | J101: 0.37574 | K101: 0.37574 | L101: 0.38097 | M101: 0.38097 | N101: 0.38455 | O101: 0.37574 | P101: 0.38097
A102: 97 | B102: 0.4434 | D102: 0.54826 | E102: 0.48842 | F102: 0.63495 | G102: 0.41165 | H102: 0.4802 | I102: 0.4802 | J102: 0.47497 | K102: 0.47497 | L102: 0.47769 | M102: 0.47769 | N102: 0.4802 | O102: 0.47497 | P102: 0.47769
A103: 98 | B103: 0.45763 | D103: 0.72467 | E103: 0.66815 | F103: 0.8686 | G103: 0.45662 | H103: 0.65798 | I103: 0.65798 | J103: 0.65585 | K103: 0.65585 | L103: 0.65738 | M103: 0.65738 | N103: 0.65798 | O103: 0.65585 | P103: 0.65738
A104: 99 | B104: 0.5 | D104: 1 | E104: 1 | F104: 1 | G104: 0.52075 | H104: 1 | I104: 1 | J104: 1 | K104: 1 | L104: 1 | M104: 1 | N104: 1 | O104: 1 | P104: 1
A105: 100 | B105: 0.5625 | G105: 0.635
A106: 101 | B106: 0.57143 | G106: 0.86877
A107: 102 | B107: 0.66667 | G107: 1
A108: 103 | B108: 1
A109: 104
A110: 105
A111: 106
A112: 107
A113: 108
A114: 109
A115: 110
A116: 111
A117: 112
A118: 113
A119: 114
A120: 115
... A126: 121

Sheet Inputs
D1: Output
A2: Mortality Table | B2: 41 | D2: Cash Value | E2: {=_xlfn.let( _xlpm.valdate, B12, _xlpm.daterange, Projection_Monthly!$B$2:$B$1050, _xlpm.cvrange, Projection_Monthly!$L$2:$L$1050, _xlpm.exactmatch, _xlfn.xlookup(_xlpm.valdate, _xlpm.daterange, _xlpm.cvrange, "", 0), IF(_xlpm.exactmatch<>"", _xlpm.exactmatch, _xlfn.let( _xlpm.datebefore, _xlfn.xlookup(_xlpm.valdate, _xlpm.daterange, _xlpm.daterange, "", -1), _xlpm.dateafter, _xlfn.xlookup(_xlpm.valdate, _xlpm.daterange, _xlpm.daterange, "", 1), _xlpm.cvbefore, _xlfn.xlookup(_xlpm.datebefore, _xlpm.daterange, _xlpm.cvrange), _xlpm.cvafter, _xlfn.xlookup(_xlpm.dateafter, _xlpm.daterange, _xlpm.cvrange), _xlpm.daysbetween, _xlpm.dateafter - _xlpm.datebefore, _xlpm.daysfrombefore, _xlpm.valdate - _xlpm.datebefore, _xlpm.fraction, _xlpm.daysfrombefore / _xlpm.daysbetween, _xlpm.cvbefore + _xlpm.fraction * (_xlpm.cvafter - _xlpm.cvbefore) ) ) )} -> #NAME? | G2: Legend
A3: Underwriting Class | B3: X | C3: Ben_info | D3: PUA Cash Value | E3: {=_xlfn.let( _xlpm.valdate, B13, _xlpm.daterange, Projection_Monthly!$B$2:$B$1050, _xlpm.cvrange, Projection_Monthly!$M$2:$M$1050, _xlpm.exactmatch, _xlfn.xlookup(_xlpm.valdate, _xlpm.daterange, _xlpm.cvrange, "", 0), IF(_xlpm.exactmatch<>"", _xlpm.exactmatch, _xlfn.let( _xlpm.datebefore, _xlfn.xlookup(_xlpm.valdate, _xlpm.daterange, _xlpm.daterange, "", -1), _xlpm.dateafter, _xlfn.xlookup(_xlpm.valdate, _xlpm.daterange, _xlpm.daterange, "", 1), _xlpm.cvbefore, _xlfn.xlookup(_xlpm.datebefore, _xlpm.daterange, _xlpm.cvrange), _xlpm.cvafter, _xlfn.xlookup(_xlpm.dateafter, _xlpm.daterange, _xlpm.cvrange), _xlpm.daysbetween, _xlpm.dateafter - _xlpm.datebefore, _xlpm.daysfrombefore, _xlpm.valdate - _xlpm.datebefore, _xlpm.fraction, _xlpm.daysfrombefore / _xlpm.daysbetween, _xlpm.cvbefore + _xlpm.fraction * (_xlpm.cvafter - _xlpm.cvbefore) ) ) )+$B$19} -> #NAME? | H3: Link with Data | K3: Matched Policies
A4: Plan Code | B4: 34 | C4: Policy_info | D4: ETI | E4: =ETI!E6 | H4: Formulae | K4: Policy Number | L4: 05451200 | M4: 13657260 | N4: 13353710 | O4: 13535530 | P4: 07340050
A5: Policy Number | B5: 07340050 | C5: Policy_info | D5: RPU | E5: =RPU!B17 | H5: Dropdown Selection | K5: Gender | L5: Male | M5: Female | N5: Female | O5: Female | P5: Female
A6: Gender | B6: M | C6: Ben_info | D6: APL | E6: =APL!F10 | K6: Units | L6: 10 | M6: 5 | N6: 2 | O6: 10 | P6: 50
A7: Issue Age | B7: =ROUND((B11-B14)/365.25,0) -> 16 | C7: Age nearest birthday | D7: Loan Outstanding | E7: =IF(B32="D",VLOOKUP("Valuation",Loan!$C$28:$G$40,5,0),IF(B32="A",VLOOKUP("Valuation",Loan!$L$28:$P$40,5,0),"Not Found")) -> 413.94772 | K7: PUA Units | P7: 159.997
A8: Premium Paying Term (PPT) | B8: 30 | C8: Enter Premium Paying Term (years) User input | K8: Issue Date | L8: 29132 | M8: 30832 | N8: 28900 | O8: 29373 | P8: 21706
A9: Units | B9: 50 | C9: Ben_info | K9: Valuation Date | L9: 46155 | M9: 46172 | N9: 46172 | O9: 46172 | P9: 46172
A10: PUA Units | B10: 159.997 | C10: Ben_info | K10: DOB | L10: 13072 | M10: 30354 | N10: 28730 | O10: 28150 | P10: 15687
A11: Issue Date | B11: 21706 | C11: Ben_info | K11: Mortality | L11: 41CSO250 | M11: 58CSO300 | N11: 58CSO300 | O11: 58CSO300 | P11: 41CSO250
A12: Valuation Date | B12: 46178 | C12: Input Value | K12: Age Basis | L12: Age Nearest | M12: Age Nearest | N12: Age Nearest | O12: Age Nearest | P12: Age Nearest
A13: Last Anniversary | B13: =IF(DATE(YEAR($B$12),MONTH($B$11),MIN(DAY($B$11), DAY(EOMONTH(DATE(YEAR($B$12),MONTH($B$11),1),0)))) <=$B$12, DATE(YEAR($B$12),MONTH($B$11),MIN(DAY($B$11), DAY(EOMONTH(DATE(YEAR($B$12),MONTH($B$11),1),0)))), DATE(YEAR($B$12)-1,MONTH($B$11),MIN(DAY($B$11), DAY(EOMONTH(DATE(YEAR($B$12)-1,MONTH($B$11),1),0))))) -> 46178
A14: DOB | B14: 15687 | C14: Name_Add
A15: Current age | B15: =ROUND(YEAR(B13)-YEAR(B14)+(MONTH(B13)-MONTH(B14))/12+(DAY(B13)-DAY(B14)-1)/360,0) -> 83 | D15: Age at Valuation Date
A16: Duration(x) | B16: =INT((B12-B11)/365.25) -> 67 | D16: Policy Duration (complete years)
A17: Duration(x+1) | B17: =B16+1 -> 68 | D17: Duration for next anniversary
A18: Base SA | B18: =B9*1000 -> 50000
A19: Declared Dividend (After Conv Date) | B19: 0 | C19: New field from Div data | D19: 2426.37
A20: Declared Dividend Rate (p.a.) | B20: 0
A21: Expense Loading Factor | B21: 0.03
A22: Dividend Option | B22: PUA
A23: Accumulation Interest Rate (p.a.) | B23: 0.025
A24: Annual Base Premium | B24: 77 | C24: Ben_info
A25: Modal Premium | B25: =B24*B27 -> 77
A26: Premium Mode | B26: Annual
A27: Modal Factor | B27: {=_xlfn.SWITCH(B26,"Annual",1,"Semi-Annual",0.5,"Quarterly",0.25,"Monthly",1/12,1)} -> 1 | C27: Policy_info
A28: Contract Status | B28: A | C28: Policy_info
A29: Premium Paid-Up Duration | B29: =MIN(B8,B16) -> 30 | D29: MIN(PPT, Duration)
A30: Is Currently Paying Premium | B30: =EDATE(B11,B8*12)>B12 -> FALSE | D30: TRUE if PPT End Date > Valuation Date
A31: Loan Intrest Rate | B31: 0.05 | C31: c_ln_loan_curr_int_rate
A32: Loan Interest Type | B32: A | C32: c_ln_loan_int_method ( A-Arrear, D- Advance)
A33: Loan Start Date | B33: 45213 | C33: c_ln_loan_curr_bal_date
A34: Starting Loan Amount | B34: 373.37 | C34: c_ln_curr_loan_balance
A35: Loan Repayment Date
A36: Repayment Amount | C36: c_ln_loan_repaid_to_date

Sheet MORTALITY
A1: Age | B1: =_xlfn.CONCAT(Inputs!B2,Inputs!B6,Inputs!B3) -> 41MX | D1: Age | E1: q_x (1958 CET ANB MALE)
A2: 0 | B2: =INDEX('CSO Rates'!$A$5:$P$126,MATCH(A2,'CSO Rates'!$A$5:$A$126,0),MATCH($B$1,'CSO Rates'!$A$4:$P$4,0)) -> 0.02258 | D2: 0 | E2: 0.00376
A3: =+A2+1 -> 1 | B3: =INDEX('CSO Rates'!$A$5:$P$126,MATCH(A3,'CSO Rates'!$A$5:$A$126,0),MATCH($B$1,'CSO Rates'!$A$4:$P$4,0)) -> 0.00577 | D3: 1 | E3: 0.00162
A4: =+A3+1 -> 2 | B4: =INDEX('CSO Rates'!$A$5:$P$126,MATCH(A4,'CSO Rates'!$A$5:$A$126,0),MATCH($B$1,'CSO Rates'!$A$4:$P$4,0)) -> 0.00414 | D4: 2 | E4: 0.00156
A5: =+A4+1 -> 3 | B5: =INDEX('CSO Rates'!$A$5:$P$126,MATCH(A5,'CSO Rates'!$A$5:$A$126,0),MATCH($B$1,'CSO Rates'!$A$4:$P$4,0)) -> 0.00338 | D5: 3 | E5: 0.00154
A6: =+A5+1 -> 4 | B6: =INDEX('CSO Rates'!$A$5:$P$126,MATCH(A6,'CSO Rates'!$A$5:$A$126,0),MATCH($B$1,'CSO Rates'!$A$4:$P$4,0)) -> 0.00299 | D6: 4 | E6: 0.00152
A7: =+A6+1 -> 5 | B7: =INDEX('CSO Rates'!$A$5:$P$126,MATCH(A7,'CSO Rates'!$A$5:$A$126,0),MATCH($B$1,'CSO Rates'!$A$4:$P$4,0)) -> 0.00276 | D7: 5 | E7: 0.00151
A8: =+A7+1 -> 6 | B8: =INDEX('CSO Rates'!$A$5:$P$126,MATCH(A8,'CSO Rates'!$A$5:$A$126,0),MATCH($B$1,'CSO Rates'!$A$4:$P$4,0)) -> 0.00261 | D8: 6 | E8: 0.00148
A9: =+A8+1 -> 7 | B9: =INDEX('CSO Rates'!$A$5:$P$126,MATCH(A9,'CSO Rates'!$A$5:$A$126,0),MATCH($B$1,'CSO Rates'!$A$4:$P$4,0)) -> 0.00247 | D9: 7 | E9: 0.00147
A10: =+A9+1 -> 8 | B10: =INDEX('CSO Rates'!$A$5:$P$126,MATCH(A10,'CSO Rates'!$A$5:$A$126,0),MATCH($B$1,'CSO Rates'!$A$4:$P$4,0)) -> 0.00231 | D10: 8 | E10: 0.00145
A11: =+A10+1 -> 9 | B11: =INDEX('CSO Rates'!$A$5:$P$126,MATCH(A11,'CSO Rates'!$A$5:$A$126,0),MATCH($B$1,'CSO Rates'!$A$4:$P$4,0)) -> 0.00212 | D11: 9 | E11: 0.00144
A12: =+A11+1 -> 10 | B12: =INDEX('CSO Rates'!$A$5:$P$126,MATCH(A12,'CSO Rates'!$A$5:$A$126,0),MATCH($B$1,'CSO Rates'!$A$4:$P$4,0)) -> 0.00197 | D12: 10 | E12: 0.00143
A13: =+A12+1 -> 11 | B13: =INDEX('CSO Rates'!$A$5:$P$126,MATCH(A13,'CSO Rates'!$A$5:$A$126,0),MATCH($B$1,'CSO Rates'!$A$4:$P$4,0)) -> 0.00191 | D13: 11 | E13: 0.00144
A14: =+A13+1 -> 12 | B14: =INDEX('CSO Rates'!$A$5:$P$126,MATCH(A14,'CSO Rates'!$A$5:$A$126,0),MATCH($B$1,'CSO Rates'!$A$4:$P$4,0)) -> 0.00192 | D14: 12 | E14: 0.00147
... A101: =+A100+1 -> 99 | B101: =INDEX('CSO Rates'!$A$5:$P$126,MATCH(A101,'CSO Rates'!$A$5:$A$126,0),MATCH($B$1,'CSO Rates'!$A$4:$P$4,0)) -> 1 | D101: 99 | E101: 1
D102: 100 | E102: 0
D103: 101 | E103: 0
D104: 102 | E104: 0
D105: 103 | E105: 0
D106: 104 | E106: 0
D107: 105 | E107: 0
D108: 106 | E108: 0
D109: 107 | E109: 0
D110: 108 | E110: 0
D111: 109 | E111: 0
D112: 110 | E112: 0
D113: 111 | E113: 0
... D122: 120 | E122: 0

Sheet Projection (Annual)
A1: Policy Number | B1: Plan Name | C1: Date | D1: Year | E1: Age | F1: Duration | G1: CV Factor (x+1) | H1: CV Factor (x) | I1: Days to next anniversary | J1: CV
A2: =Inputs!$B$5 -> 07340050 | B2: =Inputs!$B$4 -> 34 | C2: =Inputs!$B$12 -> 46178 | D2: 0 | E2: =Inputs!$B$7 -> 16 | F2: =Inputs!$B$16 -> 67 | G2: =IFERROR(INDEX(CV_RATES!$K:$K,MATCH(F2+1,CV_RATES!$C:$C,0)),0) -> 904.65633 | H2: =IFERROR(INDEX(CV_RATES!$K:$K,MATCH(F2,CV_RATES!$C:$C,0)),0) -> 899.32366 | I2: 68 | J2: =(H2*Inputs!$B$9)+(G2-H2)*Inputs!$B$9*I2/365 -> 45015.857
A3: =Inputs!$B$5 -> 07340050 | B3: =Inputs!$B$4 -> 34 | C3: =DATE(YEAR(C2)+1,MONTH(C2),DAY(C2)) -> 46543 | D3: =IF(E3<>"",D2+1) -> 1 | E3: =IF(E2<=100,E2+1,"") -> 17 | F3: =IF(D3<>"",F2+1,"") -> 68 | G3: =IFERROR(INDEX(CV_RATES!$K:$K,MATCH(F3+1,CV_RATES!$C:$C,0)),0) -> 909.75312 | H3: =IFERROR(INDEX(CV_RATES!$K:$K,MATCH(F3,CV_RATES!$C:$C,0)),0) -> 904.65633 | I3: 365 | J3: =(H3*Inputs!$B$9)+(G3-H3)*Inputs!$B$9*I3/365 -> 45487.656
A4: =Inputs!$B$5 -> 07340050 | B4: =Inputs!$B$4 -> 34 | C4: =DATE(YEAR(C3)+1,MONTH(C3),DAY(C3)) -> 46909 | D4: =IF(E4<>"",D3+1) -> 2 | E4: =IF(E3<=100,E3+1,"") -> 18 | F4: =IF(D4<>"",F3+1,"") -> 69 | G4: =IFERROR(INDEX(CV_RATES!$K:$K,MATCH(F4+1,CV_RATES!$C:$C,0)),0) -> 914.62118 | H4: =IFERROR(INDEX(CV_RATES!$K:$K,MATCH(F4,CV_RATES!$C:$C,0)),0) -> 909.75312 | I4: 365 | J4: =(H4*Inputs!$B$9)+(G4-H4)*Inputs!$B$9*I4/365 -> 45731.059
A5: =Inputs!$B$5 -> 07340050 | B5: =Inputs!$B$4 -> 34 | C5: =DATE(YEAR(C4)+1,MONTH(C4),DAY(C4)) -> 47274 | D5: =IF(E5<>"",D4+1) -> 3 | E5: =IF(E4<=100,E4+1,"") -> 19 | F5: =IF(D5<>"",F4+1,"") -> 70 | G5: =IFERROR(INDEX(CV_RATES!$K:$K,MATCH(F5+1,CV_RATES!$C:$C,0)),0) -> 919.27206 | H5: =IFERROR(INDEX(CV_RATES!$K:$K,MATCH(F5,CV_RATES!$C:$C,0)),0) -> 914.62118 | I5: 365 | J5: =(H5*Inputs!$B$9)+(G5-H5)*Inputs!$B$9*I5/365 -> 45963.603
A6: =Inputs!$B$5 -> 07340050 | B6: =Inputs!$B$4 -> 34 | C6: =DATE(YEAR(C5)+1,MONTH(C5),DAY(C5)) -> 47639 | D6: =IF(E6<>"",D5+1) -> 4 | E6: =IF(E5<=100,E5+1,"") -> 20 | F6: =IF(D6<>"",F5+1,"") -> 71 | G6: =IFERROR(INDEX(CV_RATES!$K:$K,MATCH(F6+1,CV_RATES!$C:$C,0)),0) -> 923.71713 | H6: =IFERROR(INDEX(CV_RATES!$K:$K,MATCH(F6,CV_RATES!$C:$C,0)),0) -> 919.27206 | I6: 365 | J6: =(H6*Inputs!$B$9)+(G6-H6)*Inputs!$B$9*I6/365 -> 46185.856
A7: =Inputs!$B$5 -> 07340050 | B7: =Inputs!$B$4 -> 34 | C7: =DATE(YEAR(C6)+1,MONTH(C6),DAY(C6)) -> 48004 | D7: =IF(E7<>"",D6+1) -> 5 | E7: =IF(E6<=100,E6+1,"") -> 21 | F7: =IF(D7<>"",F6+1,"") -> 72 | G7: =IFERROR(INDEX(CV_RATES!$K:$K,MATCH(F7+1,CV_RATES!$C:$C,0)),0) -> 927.98155 | H7: =IFERROR(INDEX(CV_RATES!$K:$K,MATCH(F7,CV_RATES!$C:$C,0)),0) -> 923.71713 | I7: 365 | J7: =(H7*Inputs!$B$9)+(G7-H7)*Inputs!$B$9*I7/365 -> 46399.078
A8: =Inputs!$B$5 -> 07340050 | B8: =Inputs!$B$4 -> 34 | C8: =DATE(YEAR(C7)+1,MONTH(C7),DAY(C7)) -> 48370 | D8: =IF(E8<>"",D7+1) -> 6 | E8: =IF(E7<=100,E7+1,"") -> 22 | F8: =IF(D8<>"",F7+1,"") -> 73 | G8: =IFERROR(INDEX(CV_RATES!$K:$K,MATCH(F8+1,CV_RATES!$C:$C,0)),0) -> 932.1026 | H8: =IFERROR(INDEX(CV_RATES!$K:$K,MATCH(F8,CV_RATES!$C:$C,0)),0) -> 927.98155 | I8: 365 | J8: =(H8*Inputs!$B$9)+(G8-H8)*Inputs!$B$9*I8/365 -> 46605.13
A9: =Inputs!$B$5 -> 07340050 | B9: =Inputs!$B$4 -> 34 | C9: =DATE(YEAR(C8)+1,MONTH(C8),DAY(C8)) -> 48735 | D9: =IF(E9<>"",D8+1) -> 7 | E9: =IF(E8<=100,E8+1,"") -> 23 | F9: =IF(D9<>"",F8+1,"") -> 74 | G9: =IFERROR(INDEX(CV_RATES!$K:$K,MATCH(F9+1,CV_RATES!$C:$C,0)),0) -> 936.13526 | H9: =IFERROR(INDEX(CV_RATES!$K:$K,MATCH(F9,CV_RATES!$C:$C,0)),0) -> 932.1026 | I9: 365 | J9: =(H9*Inputs!$B$9)+(G9-H9)*Inputs!$B$9*I9/365 -> 46806.763
A10: =Inputs!$B$5 -> 07340050 | B10: =Inputs!$B$4 -> 34 | C10: =DATE(YEAR(C9)+1,MONTH(C9),DAY(C9)) -> 49100 | D10: =IF(E10<>"",D9+1) -> 8 | E10: =IF(E9<=100,E9+1,"") -> 24 | F10: =IF(D10<>"",F9+1,"") -> 75 | G10: =IFERROR(INDEX(CV_RATES!$K:$K,MATCH(F10+1,CV_RATES!$C:$C,0)),0) -> 940.17778 | H10: =IFERROR(INDEX(CV_RATES!$K:$K,MATCH(F10,CV_RATES!$C:$C,0)),0) -> 936.13526 | I10: 365 | J10: =(H10*Inputs!$B$9)+(G10-H10)*Inputs!$B$9*I10/365 -> 47008.889
A11: =Inputs!$B$5 -> 07340050 | B11: =Inputs!$B$4 -> 34 | C11: =DATE(YEAR(C10)+1,MONTH(C10),DAY(C10)) -> 49465 | D11: =IF(E11<>"",D10+1) -> 9 | E11: =IF(E10<=100,E10+1,"") -> 25 | F11: =IF(D11<>"",F10+1,"") -> 76 | G11: =IFERROR(INDEX(CV_RATES!$K:$K,MATCH(F11+1,CV_RATES!$C:$C,0)),0) -> 944.41214 | H11: =IFERROR(INDEX(CV_RATES!$K:$K,MATCH(F11,CV_RATES!$C:$C,0)),0) -> 940.17778 | I11: 365 | J11: =(H11*Inputs!$B$9)+(G11-H11)*Inputs!$B$9*I11/365 -> 47220.607
A12: =Inputs!$B$5 -> 07340050 | B12: =Inputs!$B$4 -> 34 | C12: =DATE(YEAR(C11)+1,MONTH(C11),DAY(C11)) -> 49831 | D12: =IF(E12<>"",D11+1) -> 10 | E12: =IF(E11<=100,E11+1,"") -> 26 | F12: =IF(D12<>"",F11+1,"") -> 77 | G12: =IFERROR(INDEX(CV_RATES!$K:$K,MATCH(F12+1,CV_RATES!$C:$C,0)),0) -> 949.16127 | H12: =IFERROR(INDEX(CV_RATES!$K:$K,MATCH(F12,CV_RATES!$C:$C,0)),0) -> 944.41214 | I12: 365 | J12: =(H12*Inputs!$B$9)+(G12-H12)*Inputs!$B$9*I12/365 -> 47458.064
A13: =Inputs!$B$5 -> 07340050 | B13: =Inputs!$B$4 -> 34 | C13: =DATE(YEAR(C12)+1,MONTH(C12),DAY(C12)) -> 50196 | D13: =IF(E13<>"",D12+1) -> 11 | E13: =IF(E12<=100,E12+1,"") -> 27 | F13: =IF(D13<>"",F12+1,"") -> 78 | G13: =IFERROR(INDEX(CV_RATES!$K:$K,MATCH(F13+1,CV_RATES!$C:$C,0)),0) -> 955.10078 | H13: =IFERROR(INDEX(CV_RATES!$K:$K,MATCH(F13,CV_RATES!$C:$C,0)),0) -> 949.16127 | I13: 365 | J13: =(H13*Inputs!$B$9)+(G13-H13)*Inputs!$B$9*I13/365 -> 47755.039
A14: =Inputs!$B$5 -> 07340050 | B14: =Inputs!$B$4 -> 34 | C14: =DATE(YEAR(C13)+1,MONTH(C13),DAY(C13)) -> 50561 | D14: =IF(E14<>"",D13+1) -> 12 | E14: =IF(E13<=100,E13+1,"") -> 28 | F14: =IF(D14<>"",F13+1,"") -> 79 | G14: =IFERROR(INDEX(CV_RATES!$K:$K,MATCH(F14+1,CV_RATES!$C:$C,0)),0) -> 961.97302 | H14: =IFERROR(INDEX(CV_RATES!$K:$K,MATCH(F14,CV_RATES!$C:$C,0)),0) -> 955.10078 | I14: 365 | J14: =(H14*Inputs!$B$9)+(G14-H14)*Inputs!$B$9*I14/365 -> 48098.651
... A44: =Inputs!$B$5 -> 07340050 | B44: =Inputs!$B$4 -> 34 | C44: =DATE(YEAR(C43)+1,MONTH(C43),DAY(C43)) -> 61519 | D44: =IF(E44<>"",D43+1) -> 42 | E44: =IF(E43<=100,E43+1,"") -> 58 | F44: =IF(D44<>"",F43+1,"") -> 109 | G44: =IFERROR(INDEX(CV_RATES!$K:$K,MATCH(F44+1,CV_RATES!$C:$C,0)),0) -> 0 | H44: =IFERROR(INDEX(CV_RATES!$K:$K,MATCH(F44,CV_RATES!$C:$C,0)),0) -> 0 | I44: 365 | J44: =(H44*Inputs!$B$9)+(G44-H44)*Inputs!$B$9*I44/365 -> 0
A45: =Inputs!$B$5 -> 07340050 | B45: =Inputs!$B$4 -> 34 | C45: =DATE(YEAR(C44)+1,MONTH(C44),DAY(C44)) -> 61884 | D45: =IF(E45<>"",D44+1) -> 43 | E45: =IF(E44<=100,E44+1,"") -> 59 | F45: =IF(D45<>"",F44+1,"") -> 110 | G45: =IFERROR(INDEX(CV_RATES!$K:$K,MATCH(F45+1,CV_RATES!$C:$C,0)),0) -> 0 | H45: =IFERROR(INDEX(CV_RATES!$K:$K,MATCH(F45,CV_RATES!$C:$C,0)),0) -> 0 | I45: 365
A46: =Inputs!$B$5 -> 07340050 | B46: =Inputs!$B$4 -> 34 | C46: =DATE(YEAR(C45)+1,MONTH(C45),DAY(C45)) -> 62249 | D46: =IF(E46<>"",D45+1) -> 44 | E46: =IF(E45<=100,E45+1,"") -> 60 | F46: =IF(D46<>"",F45+1,"") -> 111 | G46: =IFERROR(INDEX(CV_RATES!$K:$K,MATCH(F46+1,CV_RATES!$C:$C,0)),0) -> 0 | H46: =IFERROR(INDEX(CV_RATES!$K:$K,MATCH(F46,CV_RATES!$C:$C,0)),0) -> 0 | I46: 365
A47: =Inputs!$B$5 -> 07340050 | B47: =Inputs!$B$4 -> 34 | C47: =DATE(YEAR(C46)+1,MONTH(C46),DAY(C46)) -> 62614 | D47: =IF(E47<>"",D46+1) -> 45 | E47: =IF(E46<=100,E46+1,"") -> 61 | F47: =IF(D47<>"",F46+1,"") -> 112 | G47: =IFERROR(INDEX(CV_RATES!$K:$K,MATCH(F47+1,CV_RATES!$C:$C,0)),0) -> 0 | H47: =IFERROR(INDEX(CV_RATES!$K:$K,MATCH(F47,CV_RATES!$C:$C,0)),0) -> 0 | I47: 365
A48: =Inputs!$B$5 -> 07340050 | B48: =Inputs!$B$4 -> 34 | C48: =DATE(YEAR(C47)+1,MONTH(C47),DAY(C47)) -> 62980 | D48: =IF(E48<>"",D47+1) -> 46 | E48: =IF(E47<=100,E47+1,"") -> 62 | F48: =IF(D48<>"",F47+1,"") -> 113 | G48: =IFERROR(INDEX(CV_RATES!$K:$K,MATCH(F48+1,CV_RATES!$C:$C,0)),0) -> 0 | H48: =IFERROR(INDEX(CV_RATES!$K:$K,MATCH(F48,CV_RATES!$C:$C,0)),0) -> 0 | I48: 365
A49: =Inputs!$B$5 -> 07340050 | B49: =Inputs!$B$4 -> 34 | C49: =DATE(YEAR(C48)+1,MONTH(C48),DAY(C48)) -> 63345 | D49: =IF(E49<>"",D48+1) -> 47 | E49: =IF(E48<=100,E48+1,"") -> 63 | F49: =IF(D49<>"",F48+1,"") -> 114 | G49: =IFERROR(INDEX(CV_RATES!$K:$K,MATCH(F49+1,CV_RATES!$C:$C,0)),0) -> 0 | H49: =IFERROR(INDEX(CV_RATES!$K:$K,MATCH(F49,CV_RATES!$C:$C,0)),0) -> 0 | I49: 365
A50: =Inputs!$B$5 -> 07340050 | B50: =Inputs!$B$4 -> 34 | C50: =DATE(YEAR(C49)+1,MONTH(C49),DAY(C49)) -> 63710 | D50: =IF(E50<>"",D49+1) -> 48 | E50: =IF(E49<=100,E49+1,"") -> 64 | F50: =IF(D50<>"",F49+1,"") -> 115 | G50: =IFERROR(INDEX(CV_RATES!$K:$K,MATCH(F50+1,CV_RATES!$C:$C,0)),0) -> 0 | H50: =IFERROR(INDEX(CV_RATES!$K:$K,MATCH(F50,CV_RATES!$C:$C,0)),0) -> 0 | I50: 365
A51: =Inputs!$B$5 -> 07340050 | B51: =Inputs!$B$4 -> 34 | C51: =DATE(YEAR(C50)+1,MONTH(C50),DAY(C50)) -> 64075 | D51: =IF(E51<>"",D50+1) -> 49 | E51: =IF(E50<=100,E50+1,"") -> 65 | F51: =IF(D51<>"",F50+1,"") -> 116 | G51: =IFERROR(INDEX(CV_RATES!$K:$K,MATCH(F51+1,CV_RATES!$C:$C,0)),0) -> 0 | H51: =IFERROR(INDEX(CV_RATES!$K:$K,MATCH(F51,CV_RATES!$C:$C,0)),0) -> 0 | I51: 365
A52: =Inputs!$B$5 -> 07340050 | B52: =Inputs!$B$4 -> 34 | C52: =DATE(YEAR(C51)+1,MONTH(C51),DAY(C51)) -> 64441 | D52: =IF(E52<>"",D51+1) -> 50 | E52: =IF(E51<=100,E51+1,"") -> 66 | F52: =IF(D52<>"",F51+1,"") -> 117 | G52: =IFERROR(INDEX(CV_RATES!$K:$K,MATCH(F52+1,CV_RATES!$C:$C,0)),0) -> 0 | H52: =IFERROR(INDEX(CV_RATES!$K:$K,MATCH(F52,CV_RATES!$C:$C,0)),0) -> 0 | I52: 365
A53: =Inputs!$B$5 -> 07340050 | B53: =Inputs!$B$4 -> 34 | C53: =DATE(YEAR(C52)+1,MONTH(C52),DAY(C52)) -> 64806 | D53: =IF(E53<>"",D52+1) -> 51 | E53: =IF(E52<=100,E52+1,"") -> 67 | F53: =IF(D53<>"",F52+1,"") -> 118 | G53: =IFERROR(INDEX(CV_RATES!$K:$K,MATCH(F53+1,CV_RATES!$C:$C,0)),0) -> 0 | H53: =IFERROR(INDEX(CV_RATES!$K:$K,MATCH(F53,CV_RATES!$C:$C,0)),0) -> 0 | I53: 365
A54: =Inputs!$B$5 -> 07340050 | B54: =Inputs!$B$4 -> 34 | C54: =DATE(YEAR(C53)+1,MONTH(C53),DAY(C53)) -> 65171 | D54: =IF(E54<>"",D53+1) -> 52 | E54: =IF(E53<=100,E53+1,"") -> 68 | F54: =IF(D54<>"",F53+1,"") -> 119 | G54: =IFERROR(INDEX(CV_RATES!$K:$K,MATCH(F54+1,CV_RATES!$C:$C,0)),0) -> 0 | H54: =IFERROR(INDEX(CV_RATES!$K:$K,MATCH(F54,CV_RATES!$C:$C,0)),0) -> 0 | I54: 365
A55: =Inputs!$B$5 -> 07340050 | B55: =Inputs!$B$4 -> 34 | C55: =DATE(YEAR(C54)+1,MONTH(C54),DAY(C54)) -> 65536 | D55: =IF(E55<>"",D54+1) -> 53 | E55: =IF(E54<=100,E54+1,"") -> 69 | F55: =IF(D55<>"",F54+1,"") -> 120 | G55: =IFERROR(INDEX(CV_RATES!$K:$K,MATCH(F55+1,CV_RATES!$C:$C,0)),0) -> 0 | H55: =IFERROR(INDEX(CV_RATES!$K:$K,MATCH(F55,CV_RATES!$C:$C,0)),0) -> 0 | I55: 365
A56: =Inputs!$B$5 -> 07340050 | B56: =Inputs!$B$4 -> 34 | C56: =DATE(YEAR(C55)+1,MONTH(C55),DAY(C55)) -> 65902 | D56: =IF(E56<>"",D55+1) -> 54 | E56: =IF(E55<=100,E55+1,"") -> 70 | F56: =IF(D56<>"",F55+1,"") -> 121 | G56: =IFERROR(INDEX(CV_RATES!$K:$K,MATCH(F56+1,CV_RATES!$C:$C,0)),0) -> 0 | H56: =IFERROR(INDEX(CV_RATES!$K:$K,MATCH(F56,CV_RATES!$C:$C,0)),0) -> 0 | I56: 365
... A100: =Inputs!$B$5 -> 07340050 | B100: =Inputs!$B$4 -> 34 | C100: =DATE(YEAR(C99)+1,MONTH(C99),DAY(C99)) -> 81972 | D100: =IF(E100<>"",D99+1) -> FALSE | E100: =IF(E99<=100,E99+1,"") | F100: =IF(D100<>"",F99+1,"") -> 165 | G100: =IFERROR(INDEX(CV_RATES!$K:$K,MATCH(F100+1,CV_RATES!$C:$C,0)),0) -> 0 | H100: =IFERROR(INDEX(CV_RATES!$K:$K,MATCH(F100,CV_RATES!$C:$C,0)),0) -> 0 | I100: 365

Sheet Commutation
A1: Age | B1: qx | C1: lx | D1: dx | E1: v^x | F1: Dx | G1: Cx | H1: Nx | I1: Mx | J1: ax_due | K1: Ax | L1: NLP_per_1000 | M1: LPP_NLP_per_1000
A2: 0 | B2: =IF(A2="","",IFERROR(INDEX(MORTALITY!$B:$B,MATCH(A2,MORTALITY!$A:$A,0)),0)) -> 0.02258 | C2: 10000000 | D2: =IF(A2="","",IFERROR(C2*B2,0)) -> 225800 | E2: =IF(A2="","",IFERROR((1/(1+Inputs!$B$23))^A2,0)) -> 1 | F2: =IF(A2="","",IFERROR(C2*E2,0)) -> 10000000 | G2: =IF(A2="","",IFERROR(D2*(1/(1+Inputs!$B$23))^(A2+1),0)) -> 220292.68 | H2: =IF(A2="","",IFERROR(IF(B2=1,F2,F2+H3),0)) -> 3.0665805e+08 | I2: =IF(A2="","",IFERROR(IF(B2=1,G2,G2+I3),0)) -> 2520535.3 | J2: =IF(A2="","",IFERROR(H2/F2,0)) -> 30.665805 | K2: =IF(A2="","",IFERROR(I2/F2,0)) -> 0.25205353 | L2: =IF(A2="","",IFERROR(1000*I2/H2,0)) -> 8.2193676 | M2: =IF(A2="","",IFERROR(1000*I2/(H2-INDEX(H:H,MATCH(A2+Inputs!$B$8,$A:$A,0))),0)) -> 12.409866
A3: =IF(OR(A2="",A2>=MAX(MORTALITY!$A:$A)),"",A2+1) -> 1 | B3: =IF(A3="","",IFERROR(INDEX(MORTALITY!$B:$B,MATCH(A3,MORTALITY!$A:$A,0)),0)) -> 0.00577 | C3: =IF(A3="","",IFERROR(C2*(1-B2),0)) -> 9774200 | D3: =IF(A3="","",IFERROR(C3*B3,0)) -> 56397.134 | E3: =IF(A3="","",IFERROR((1/(1+Inputs!$B$23))^A3,0)) -> 0.97560976 | F3: =IF(A3="","",IFERROR(C3*E3,0)) -> 9535804.9 | G3: =IF(A3="","",IFERROR(D3*(1/(1+Inputs!$B$23))^(A3+1),0)) -> 53679.604 | H3: =IF(A3="","",IFERROR(IF(B3=1,F3,F3+H4),0)) -> 2.9665805e+08 | I3: =IF(A3="","",IFERROR(IF(B3=1,G3,G3+I4),0)) -> 2300242.6 | J3: =IF(A3="","",IFERROR(H3/F3,0)) -> 31.109912 | K3: =IF(A3="","",IFERROR(I3/F3,0)) -> 0.24122165 | L3: =IF(A3="","",IFERROR(1000*I3/H3,0)) -> 7.7538518 | M3: =IF(A3="","",IFERROR(1000*I3/(H3-INDEX(H:H,MATCH(A3+Inputs!$B$8,$A:$A,0))),0)) -> 11.651763
A4: =IF(OR(A3="",A3>=MAX(MORTALITY!$A:$A)),"",A3+1) -> 2 | B4: =IF(A4="","",IFERROR(INDEX(MORTALITY!$B:$B,MATCH(A4,MORTALITY!$A:$A,0)),0)) -> 0.00414 | C4: =IF(A4="","",IFERROR(C3*(1-B3),0)) -> 9717802.9 | D4: =IF(A4="","",IFERROR(C4*B4,0)) -> 40231.704 | E4: =IF(A4="","",IFERROR((1/(1+Inputs!$B$23))^A4,0)) -> 0.9518144 | F4: =IF(A4="","",IFERROR(C4*E4,0)) -> 9249544.7 | G4: =IF(A4="","",IFERROR(D4*(1/(1+Inputs!$B$23))^(A4+1),0)) -> 37359.137 | H4: =IF(A4="","",IFERROR(IF(B4=1,F4,F4+H5),0)) -> 2.8712225e+08 | I4: =IF(A4="","",IFERROR(IF(B4=1,G4,G4+I5),0)) -> 2246563 | J4: =IF(A4="","",IFERROR(H4/F4,0)) -> 31.041771 | K4: =IF(A4="","",IFERROR(I4/F4,0)) -> 0.24288363 | L4: =IF(A4="","",IFERROR(1000*I4/H4,0)) -> 7.8244128 | M4: =IF(A4="","",IFERROR(1000*I4/(H4-INDEX(H:H,MATCH(A4+Inputs!$B$8,$A:$A,0))),0)) -> 11.696678
A5: =IF(OR(A4="",A4>=MAX(MORTALITY!$A:$A)),"",A4+1) -> 3 | B5: =IF(A5="","",IFERROR(INDEX(MORTALITY!$B:$B,MATCH(A5,MORTALITY!$A:$A,0)),0)) -> 0.00338 | C5: =IF(A5="","",IFERROR(C4*(1-B4),0)) -> 9677571.2 | D5: =IF(A5="","",IFERROR(C5*B5,0)) -> 32710.191 | E5: =IF(A5="","",IFERROR((1/(1+Inputs!$B$23))^A5,0)) -> 0.92859941 | F5: =IF(A5="","",IFERROR(C5*E5,0)) -> 8986586.9 | G5: =IF(A5="","",IFERROR(D5*(1/(1+Inputs!$B$23))^(A5+1),0)) -> 29633.818 | H5: =IF(A5="","",IFERROR(IF(B5=1,F5,F5+H6),0)) -> 2.778727e+08 | I5: =IF(A5="","",IFERROR(IF(B5=1,G5,G5+I6),0)) -> 2209203.9 | J5: =IF(A5="","",IFERROR(H5/F5,0)) -> 30.920828 | K5: =IF(A5="","",IFERROR(I5/F5,0)) -> 0.24583347 | L5: =IF(A5="","",IFERROR(1000*I5/H5,0)) -> 7.9504169 | M5: =IF(A5="","",IFERROR(1000*I5/(H5-INDEX(H:H,MATCH(A5+Inputs!$B$8,$A:$A,0))),0)) -> 11.820881
A6: =IF(OR(A5="",A5>=MAX(MORTALITY!$A:$A)),"",A5+1) -> 4 | B6: =IF(A6="","",IFERROR(INDEX(MORTALITY!$B:$B,MATCH(A6,MORTALITY!$A:$A,0)),0)) -> 0.00299 | C6: =IF(A6="","",IFERROR(C5*(1-B5),0)) -> 9644861 | D6: =IF(A6="","",IFERROR(C6*B6,0)) -> 28838.134 | E6: =IF(A6="","",IFERROR((1/(1+Inputs!$B$23))^A6,0)) -> 0.90595064 | F6: =IF(A6="","",IFERROR(C6*E6,0)) -> 8737768 | G6: =IF(A6="","",IFERROR(D6*(1/(1+Inputs!$B$23))^(A6+1),0)) -> 25488.709 | H6: =IF(A6="","",IFERROR(IF(B6=1,F6,F6+H7),0)) -> 2.6888612e+08 | I6: =IF(A6="","",IFERROR(IF(B6=1,G6,G6+I7),0)) -> 2179570 | J6: =IF(A6="","",IFERROR(H6/F6,0)) -> 30.772861 | K6: =IF(A6="","",IFERROR(I6/F6,0)) -> 0.24944242 | L6: =IF(A6="","",IFERROR(1000*I6/H6,0)) -> 8.1059225 | M6: =IF(A6="","",IFERROR(1000*I6/(H6-INDEX(H:H,MATCH(A6+Inputs!$B$8,$A:$A,0))),0)) -> 11.98491
A7: =IF(OR(A6="",A6>=MAX(MORTALITY!$A:$A)),"",A6+1) -> 5 | B7: =IF(A7="","",IFERROR(INDEX(MORTALITY!$B:$B,MATCH(A7,MORTALITY!$A:$A,0)),0)) -> 0.00276 | C7: =IF(A7="","",IFERROR(C6*(1-B6),0)) -> 9616022.8 | D7: =IF(A7="","",IFERROR(C7*B7,0)) -> 26540.223 | E7: =IF(A7="","",IFERROR((1/(1+Inputs!$B$23))^A7,0)) -> 0.88385429 | F7: =IF(A7="","",IFERROR(C7*E7,0)) -> 8499163 | G7: =IF(A7="","",IFERROR(D7*(1/(1+Inputs!$B$23))^(A7+1),0)) -> 22885.551 | H7: =IF(A7="","",IFERROR(IF(B7=1,F7,F7+H8),0)) -> 2.6014835e+08 | I7: =IF(A7="","",IFERROR(IF(B7=1,G7,G7+I8),0)) -> 2154081.3 | J7: =IF(A7="","",IFERROR(H7/F7,0)) -> 30.608702 | K7: =IF(A7="","",IFERROR(I7/F7,0)) -> 0.25344629 | L7: =IF(A7="","",IFERROR(1000*I7/H7,0)) -> 8.2802037 | M7: =IF(A7="","",IFERROR(1000*I7/(H7-INDEX(H:H,MATCH(A7+Inputs!$B$8,$A:$A,0))),0)) -> 12.172322
A8: =IF(OR(A7="",A7>=MAX(MORTALITY!$A:$A)),"",A7+1) -> 6 | B8: =IF(A8="","",IFERROR(INDEX(MORTALITY!$B:$B,MATCH(A8,MORTALITY!$A:$A,0)),0)) -> 0.00261 | C8: =IF(A8="","",IFERROR(C7*(1-B7),0)) -> 9589482.6 | D8: =IF(A8="","",IFERROR(C8*B8,0)) -> 25028.55 | E8: =IF(A8="","",IFERROR((1/(1+Inputs!$B$23))^A8,0)) -> 0.86229687 | F8: =IF(A8="","",IFERROR(C8*E8,0)) -> 8268980.8 | G8: =IF(A8="","",IFERROR(D8*(1/(1+Inputs!$B$23))^(A8+1),0)) -> 21055.649 | H8: =IF(A8="","",IFERROR(IF(B8=1,F8,F8+H9),0)) -> 2.5164919e+08 | I8: =IF(A8="","",IFERROR(IF(B8=1,G8,G8+I9),0)) -> 2131195.8 | J8: =IF(A8="","",IFERROR(H8/F8,0)) -> 30.432915 | K8: =IF(A8="","",IFERROR(I8/F8,0)) -> 0.25773379 | L8: =IF(A8="","",IFERROR(1000*I8/H8,0)) -> 8.4689158 | M8: =IF(A8="","",IFERROR(1000*I8/(H8-INDEX(H:H,MATCH(A8+Inputs!$B$8,$A:$A,0))),0)) -> 12.376278
A9: =IF(OR(A8="",A8>=MAX(MORTALITY!$A:$A)),"",A8+1) -> 7 | B9: =IF(A9="","",IFERROR(INDEX(MORTALITY!$B:$B,MATCH(A9,MORTALITY!$A:$A,0)),0)) -> 0.00247 | C9: =IF(A9="","",IFERROR(C8*(1-B8),0)) -> 9564454.1 | D9: =IF(A9="","",IFERROR(C9*B9,0)) -> 23624.202 | E9: =IF(A9="","",IFERROR((1/(1+Inputs!$B$23))^A9,0)) -> 0.84126524 | F9: =IF(A9="","",IFERROR(C9*E9,0)) -> 8046242.7 | G9: =IF(A9="","",IFERROR(D9*(1/(1+Inputs!$B$23))^(A9+1),0)) -> 19389.482 | H9: =IF(A9="","",IFERROR(IF(B9=1,F9,F9+H10),0)) -> 2.4338021e+08 | I9: =IF(A9="","",IFERROR(IF(B9=1,G9,G9+I10),0)) -> 2110140.1 | J9: =IF(A9="","",IFERROR(H9/F9,0)) -> 30.247684 | K9: =IF(A9="","",IFERROR(I9/F9,0)) -> 0.26225161 | L9: =IF(A9="","",IFERROR(1000*I9/H9,0)) -> 8.6701387 | M9: =IF(A9="","",IFERROR(1000*I9/(H9-INDEX(H:H,MATCH(A9+Inputs!$B$8,$A:$A,0))),0)) -> 12.593566
A10: =IF(OR(A9="",A9>=MAX(MORTALITY!$A:$A)),"",A9+1) -> 8 | B10: =IF(A10="","",IFERROR(INDEX(MORTALITY!$B:$B,MATCH(A10,MORTALITY!$A:$A,0)),0)) -> 0.00231 | C10: =IF(A10="","",IFERROR(C9*(1-B9),0)) -> 9540829.9 | D10: =IF(A10="","",IFERROR(C10*B10,0)) -> 22039.317 | E10: =IF(A10="","",IFERROR((1/(1+Inputs!$B$23))^A10,0)) -> 0.82074657 | F10: =IF(A10="","",IFERROR(C10*E10,0)) -> 7830603.4 | G10: =IF(A10="","",IFERROR(D10*(1/(1+Inputs!$B$23))^(A10+1),0)) -> 17647.506 | H10: =IF(A10="","",IFERROR(IF(B10=1,F10,F10+H11),0)) -> 2.3533396e+08 | I10: =IF(A10="","",IFERROR(IF(B10=1,G10,G10+I11),0)) -> 2090750.6 | J10: =IF(A10="","",IFERROR(H10/F10,0)) -> 30.053107 | K10: =IF(A10="","",IFERROR(I10/F10,0)) -> 0.26699739 | L10: =IF(A10="","",IFERROR(1000*I10/H10,0)) -> 8.8841858 | M10: =IF(A10="","",IFERROR(1000*I10/(H10-INDEX(H:H,MATCH(A10+Inputs!$B$8,$A:$A,0))),0)) -> 12.824248
A11: =IF(OR(A10="",A10>=MAX(MORTALITY!$A:$A)),"",A10+1) -> 9 | B11: =IF(A11="","",IFERROR(INDEX(MORTALITY!$B:$B,MATCH(A11,MORTALITY!$A:$A,0)),0)) -> 0.00212 | C11: =IF(A11="","",IFERROR(C10*(1-B10),0)) -> 9518790.5 | D11: =IF(A11="","",IFERROR(C11*B11,0)) -> 20179.836 | E11: =IF(A11="","",IFERROR((1/(1+Inputs!$B$23))^A11,0)) -> 0.80072836 | F11: =IF(A11="","",IFERROR(C11*E11,0)) -> 7621965.6 | G11: =IF(A11="","",IFERROR(D11*(1/(1+Inputs!$B$23))^(A11+1),0)) -> 15764.456 | H11: =IF(A11="","",IFERROR(IF(B11=1,F11,F11+H12),0)) -> 2.2750336e+08 | I11: =IF(A11="","",IFERROR(IF(B11=1,G11,G11+I12),0)) -> 2073103.1 | J11: =IF(A11="","",IFERROR(H11/F11,0)) -> 29.848385 | K11: =IF(A11="","",IFERROR(I11/F11,0)) -> 0.27199062 | L11: =IF(A11="","",IFERROR(1000*I11/H11,0)) -> 9.1124067 | M11: =IF(A11="","",IFERROR(1000*I11/(H11-INDEX(H:H,MATCH(A11+Inputs!$B$8,$A:$A,0))),0)) -> 13.069852
A12: =IF(OR(A11="",A11>=MAX(MORTALITY!$A:$A)),"",A11+1) -> 10 | B12: =IF(A12="","",IFERROR(INDEX(MORTALITY!$B:$B,MATCH(A12,MORTALITY!$A:$A,0)),0)) -> 0.00197 | C12: =IF(A12="","",IFERROR(C11*(1-B11),0)) -> 9498610.7 | D12: =IF(A12="","",IFERROR(C12*B12,0)) -> 18712.263 | E12: =IF(A12="","",IFERROR((1/(1+Inputs!$B$23))^A12,0)) -> 0.7811984 | F12: =IF(A12="","",IFERROR(C12*E12,0)) -> 7420299.5 | G12: =IF(A12="","",IFERROR(D12*(1/(1+Inputs!$B$23))^(A12+1),0)) -> 14261.454 | H12: =IF(A12="","",IFERROR(IF(B12=1,F12,F12+H13),0)) -> 2.1988139e+08 | I12: =IF(A12="","",IFERROR(IF(B12=1,G12,G12+I13),0)) -> 2057338.7 | J12: =IF(A12="","",IFERROR(H12/F12,0)) -> 29.632415 | K12: =IF(A12="","",IFERROR(I12/F12,0)) -> 0.27725817 | L12: =IF(A12="","",IFERROR(1000*I12/H12,0)) -> 9.3565838 | M12: =IF(A12="","",IFERROR(1000*I12/(H12-INDEX(H:H,MATCH(A12+Inputs!$B$8,$A:$A,0))),0)) -> 13.332467
A13: =IF(OR(A12="",A12>=MAX(MORTALITY!$A:$A)),"",A12+1) -> 11 | B13: =IF(A13="","",IFERROR(INDEX(MORTALITY!$B:$B,MATCH(A13,MORTALITY!$A:$A,0)),0)) -> 0.00191 | C13: =IF(A13="","",IFERROR(C12*(1-B12),0)) -> 9479898.4 | D13: =IF(A13="","",IFERROR(C13*B13,0)) -> 18106.606 | E13: =IF(A13="","",IFERROR((1/(1+Inputs!$B$23))^A13,0)) -> 0.76214478 | F13: =IF(A13="","",IFERROR(C13*E13,0)) -> 7225055.1 | G13: =IF(A13="","",IFERROR(D13*(1/(1+Inputs!$B$23))^(A13+1),0)) -> 13463.273 | H13: =IF(A13="","",IFERROR(IF(B13=1,F13,F13+H14),0)) -> 2.1246109e+08 | I13: =IF(A13="","",IFERROR(IF(B13=1,G13,G13+I14),0)) -> 2043077.2 | J13: =IF(A13="","",IFERROR(H13/F13,0)) -> 29.406155 | K13: =IF(A13="","",IFERROR(I13/F13,0)) -> 0.2827767 | L13: =IF(A13="","",IFERROR(1000*I13/H13,0)) -> 9.6162417 | M13: =IF(A13="","",IFERROR(1000*I13/(H13-INDEX(H:H,MATCH(A13+Inputs!$B$8,$A:$A,0))),0)) -> 13.610925
A14: =IF(OR(A13="",A13>=MAX(MORTALITY!$A:$A)),"",A13+1) -> 12 | B14: =IF(A14="","",IFERROR(INDEX(MORTALITY!$B:$B,MATCH(A14,MORTALITY!$A:$A,0)),0)) -> 0.00192 | C14: =IF(A14="","",IFERROR(C13*(1-B13),0)) -> 9461791.8 | D14: =IF(A14="","",IFERROR(C14*B14,0)) -> 18166.64 | E14: =IF(A14="","",IFERROR((1/(1+Inputs!$B$23))^A14,0)) -> 0.74355589 | F14: =IF(A14="","",IFERROR(C14*E14,0)) -> 7035371 | G14: =IF(A14="","",IFERROR(D14*(1/(1+Inputs!$B$23))^(A14+1),0)) -> 13178.451 | H14: =IF(A14="","",IFERROR(IF(B14=1,F14,F14+H15),0)) -> 2.0523604e+08 | I14: =IF(A14="","",IFERROR(IF(B14=1,G14,G14+I15),0)) -> 2029614 | J14: =IF(A14="","",IFERROR(H14/F14,0)) -> 29.172028 | K14: =IF(A14="","",IFERROR(I14/F14,0)) -> 0.28848712 | L14: =IF(A14="","",IFERROR(1000*I14/H14,0)) -> 9.8891694 | M14: =IF(A14="","",IFERROR(1000*I14/(H14-INDEX(H:H,MATCH(A14+Inputs!$B$8,$A:$A,0))),0)) -> 13.901621
... A110: =IF(OR(A109="",A109>=MAX(MORTALITY!$A:$A)),"",A109+1) | B110: =IF(A110="","",IFERROR(INDEX(MORTALITY!$B:$B,MATCH(A110,MORTALITY!$A:$A,0)),0)) | C110: =IF(A110="","",IFERROR(C109*(1-B109),0)) | D110: =IF(A110="","",IFERROR(C110*B110,0)) | E110: =IF(A110="","",IFERROR((1/(1+Inputs!$B$23))^A110,0)) | F110: =IF(A110="","",IFERROR(C110*E110,0)) | G110: =IF(A110="","",IFERROR(D110*(1/(1+Inputs!$B$23))^(A110+1),0)) | H110: =IF(A110="","",IFERROR(IF(B110=1,F110,F110+H111),0)) | I110: =IF(A110="","",IFERROR(IF(B110=1,G110,G110+I111),0)) | J110: =IF(A110="","",IFERROR(H110/F110,0)) | K110: =IF(A110="","",IFERROR(I110/F110,0)) | L110: =IF(A110="","",IFERROR(1000*I110/H110,0)) | M110: =IF(A110="","",IFERROR(1000*I110/(H110-INDEX(H:H,MATCH(A110+Inputs!$B$8,$A:$A,0))),0))

Sheet CV_RATES
A1: Code | B1: Issue Age | C1: Duration | D1: Attained Age | E1: qx | F1: px | G1: Interest Rate | H1: Beta (NLP/1000) | I1: CV (BOY) | J1: CV (EOY) | K1: CV FACTOR
A2: =IF(D2>100,"",Inputs!$B$4) -> 34 | B2: =IF(D2>100,"",Inputs!$B$7) -> 16 | C2: 0 | D2: =IFERROR(IF(Inputs!$B$7+C2>=100,"",Inputs!$B$7+C2),"") -> 16 | E2: =IF(D2="","",INDEX(MORTALITY!$B:$B,MATCH(D2,MORTALITY!$A:$A,0))) -> 0.00219 | F2: =IF(D2="","",1-E2) -> 0.99781 | G2: =IF(D2="","",Inputs!$B$23) -> 0.025 | H2: =IF(D2="","",INDEX(Commutation!$L:$L,MATCH(Inputs!$B$7,Commutation!$A:$A,0))) -> 11.090171 | I2: 0 | J2: =IF(D2>99,"",IF(E2=1,1000,MIN(1000,MAX(0,(INDEX(Commutation!$K:$K,MATCH(D3,Commutation!$A:$A,0))-(INDEX(Commutation!$K:$K,MATCH(Inputs!$B$7,Commutation!$A:$A,0))/((INDEX(Commutation!$H:$H,MATCH(Inputs!$B$7,Commutation!$A:$A,0))-INDEX(Commutation!$H:$H,MATCH(Inputs!$B$8,Commutation!$A:$A,0)))/INDEX(Commutation!$F:$F,MATCH(Inputs!$B$7,Commutation!$A:$A,0))))*MAX(0,(INDEX(Commutation!$H:$H,MATCH(D3,Commutation!$A:$A,0))-INDEX(Commutation!$H:$H,MATCH(Inputs!$B$8,Commutation!$A:$A,0)))/INDEX(Commutation!$F:$F,MATCH(D3,Commutation!$A:$A,0))))*1000)))) -> 25.003668 | K2: =J2 -> 25.003668 | M2: =IF(A2="","",IF(E2=1,1000,IFERROR(((I2+IF(C2<=Inputs!$B$8,$H$2,0))*(1+G2)-E2*1000)/F2,0))) -> 9.1975681
A3: =IF(D3>100,"",Inputs!$B$4) -> 34 | B3: =IF(D3>100,"",Inputs!$B$7) -> 16 | C3: =IFERROR(IF(Inputs!$B$7+C2+1>=100,"",C2+1),"") -> 1 | D3: =IFERROR(IF(Inputs!$B$7+C3>=100,"",Inputs!$B$7+C3),"") -> 17 | E3: =IF(D3="","",INDEX(MORTALITY!$B:$B,MATCH(D3,MORTALITY!$A:$A,0))) -> 0.00225 | F3: =IF(D3="","",1-E3) -> 0.99775 | G3: =IF(D3="","",Inputs!$B$23) -> 0.025 | H3: =IF(D3="","",INDEX(Commutation!$L:$L,MATCH(Inputs!$B$7,Commutation!$A:$A,0))) -> 11.090171 | I3: =IF(D3="","",J2) -> 25.003668 | J3: =IF(D3>99,"",IF(E3=1,1000,MIN(1000,MAX(0,(INDEX(Commutation!$K:$K,MATCH(D4,Commutation!$A:$A,0))-(INDEX(Commutation!$K:$K,MATCH(Inputs!$B$7,Commutation!$A:$A,0))/((INDEX(Commutation!$H:$H,MATCH(Inputs!$B$7,Commutation!$A:$A,0))-INDEX(Commutation!$H:$H,MATCH(Inputs!$B$8,Commutation!$A:$A,0)))/INDEX(Commutation!$F:$F,MATCH(Inputs!$B$7,Commutation!$A:$A,0))))*MAX(0,(INDEX(Commutation!$H:$H,MATCH(D4,Commutation!$A:$A,0))-INDEX(Commutation!$H:$H,MATCH(Inputs!$B$8,Commutation!$A:$A,0)))/INDEX(Commutation!$F:$F,MATCH(D4,Commutation!$A:$A,0))))*1000)))) -> 50.63159 | K3: =J3 -> 50.63159 | M3: =IF(A3="","",IF(E3=1,1000,IFERROR(((I3+IF(C3<=Inputs!$B$8,$H$2,0))*(1+G3)-E3*1000)/F3,0))) -> 34.82454
A4: =IF(D4>100,"",Inputs!$B$4) -> 34 | B4: =IF(D4>100,"",Inputs!$B$7) -> 16 | C4: =IFERROR(IF(Inputs!$B$7+C3+1>=100,"",C3+1),"") -> 2 | D4: =IFERROR(IF(Inputs!$B$7+C4>=100,"",Inputs!$B$7+C4),"") -> 18 | E4: =IF(D4="","",INDEX(MORTALITY!$B:$B,MATCH(D4,MORTALITY!$A:$A,0))) -> 0.0023 | F4: =IF(D4="","",1-E4) -> 0.9977 | G4: =IF(D4="","",Inputs!$B$23) -> 0.025 | H4: =IF(D4="","",INDEX(Commutation!$L:$L,MATCH(Inputs!$B$7,Commutation!$A:$A,0))) -> 11.090171 | I4: =IF(D4="","",J3) -> 50.63159 | J4: =IF(D4>99,"",IF(E4=1,1000,MIN(1000,MAX(0,(INDEX(Commutation!$K:$K,MATCH(D5,Commutation!$A:$A,0))-(INDEX(Commutation!$K:$K,MATCH(Inputs!$B$7,Commutation!$A:$A,0))/((INDEX(Commutation!$H:$H,MATCH(Inputs!$B$7,Commutation!$A:$A,0))-INDEX(Commutation!$H:$H,MATCH(Inputs!$B$8,Commutation!$A:$A,0)))/INDEX(Commutation!$F:$F,MATCH(Inputs!$B$7,Commutation!$A:$A,0))))*MAX(0,(INDEX(Commutation!$H:$H,MATCH(D5,Commutation!$A:$A,0))-INDEX(Commutation!$H:$H,MATCH(Inputs!$B$8,Commutation!$A:$A,0)))/INDEX(Commutation!$F:$F,MATCH(D5,Commutation!$A:$A,0))))*1000)))) -> 76.91319 | K4: =IF(Inputs!$B$7+3-1>MAX(MORTALITY!$A:$A),"",IFERROR(J4,0)) -> 76.91319 | M4: =IF(A4="","",IF(E4=1,1000,IFERROR(((I4+IF(C4<=Inputs!$B$8,$H$2,0))*(1+G4)-E4*1000)/F4,0))) -> 61.105347
A5: =IF(D5>100,"",Inputs!$B$4) -> 34 | B5: =IF(D5>100,"",Inputs!$B$7) -> 16 | C5: =IFERROR(IF(Inputs!$B$7+C4+1>=100,"",C4+1),"") -> 3 | D5: =IFERROR(IF(Inputs!$B$7+C5>=100,"",Inputs!$B$7+C5),"") -> 19 | E5: =IF(D5="","",INDEX(MORTALITY!$B:$B,MATCH(D5,MORTALITY!$A:$A,0))) -> 0.00237 | F5: =IF(D5="","",1-E5) -> 0.99763 | G5: =IF(D5="","",Inputs!$B$23) -> 0.025 | H5: =IF(D5="","",INDEX(Commutation!$L:$L,MATCH(Inputs!$B$7,Commutation!$A:$A,0))) -> 11.090171 | I5: =IF(D5="","",J4) -> 76.91319 | J5: =IF(D5>99,"",IF(E5=1,1000,MIN(1000,MAX(0,(INDEX(Commutation!$K:$K,MATCH(D6,Commutation!$A:$A,0))-(INDEX(Commutation!$K:$K,MATCH(Inputs!$B$7,Commutation!$A:$A,0))/((INDEX(Commutation!$H:$H,MATCH(Inputs!$B$7,Commutation!$A:$A,0))-INDEX(Commutation!$H:$H,MATCH(Inputs!$B$8,Commutation!$A:$A,0)))/INDEX(Commutation!$F:$F,MATCH(Inputs!$B$7,Commutation!$A:$A,0))))*MAX(0,(INDEX(Commutation!$H:$H,MATCH(D6,Commutation!$A:$A,0))-INDEX(Commutation!$H:$H,MATCH(Inputs!$B$8,Commutation!$A:$A,0)))/INDEX(Commutation!$F:$F,MATCH(D6,Commutation!$A:$A,0))))*1000)))) -> 103.85106 | K5: =IF(Inputs!$B$7+4-1>MAX(MORTALITY!$A:$A),"",IFERROR(J5,0)) -> 103.85106 | M5: =IF(A5="","",IF(E5=1,1000,IFERROR(((I5+IF(C5<=Inputs!$B$8,$H$2,0))*(1+G5)-E5*1000)/F5,0))) -> 88.042105
A6: =IF(D6>100,"",Inputs!$B$4) -> 34 | B6: =IF(D6>100,"",Inputs!$B$7) -> 16 | C6: =IFERROR(IF(Inputs!$B$7+C5+1>=100,"",C5+1),"") -> 4 | D6: =IFERROR(IF(Inputs!$B$7+C6>=100,"",Inputs!$B$7+C6),"") -> 20 | E6: =IF(D6="","",INDEX(MORTALITY!$B:$B,MATCH(D6,MORTALITY!$A:$A,0))) -> 0.00243 | F6: =IF(D6="","",1-E6) -> 0.99757 | G6: =IF(D6="","",Inputs!$B$23) -> 0.025 | H6: =IF(D6="","",INDEX(Commutation!$L:$L,MATCH(Inputs!$B$7,Commutation!$A:$A,0))) -> 11.090171 | I6: =IF(D6="","",J5) -> 103.85106 | J6: =IF(D6>99,"",IF(E6=1,1000,MIN(1000,MAX(0,(INDEX(Commutation!$K:$K,MATCH(D7,Commutation!$A:$A,0))-(INDEX(Commutation!$K:$K,MATCH(Inputs!$B$7,Commutation!$A:$A,0))/((INDEX(Commutation!$H:$H,MATCH(Inputs!$B$7,Commutation!$A:$A,0))-INDEX(Commutation!$H:$H,MATCH(Inputs!$B$8,Commutation!$A:$A,0)))/INDEX(Commutation!$F:$F,MATCH(Inputs!$B$7,Commutation!$A:$A,0))))*MAX(0,(INDEX(Commutation!$H:$H,MATCH(D7,Commutation!$A:$A,0))-INDEX(Commutation!$H:$H,MATCH(Inputs!$B$8,Commutation!$A:$A,0)))/INDEX(Commutation!$F:$F,MATCH(D7,Commutation!$A:$A,0))))*1000)))) -> 131.47573 | K6: =IF(Inputs!$B$7+5-1>MAX(MORTALITY!$A:$A),"",IFERROR(J6,0)) -> 131.47573 | M6: =IF(A6="","",IF(E6=1,1000,IFERROR(((I6+IF(C6<=Inputs!$B$8,$H$2,0))*(1+G6)-E6*1000)/F6,0))) -> 115.66583
A7: =IF(D7>100,"",Inputs!$B$4) -> 34 | B7: =IF(D7>100,"",Inputs!$B$7) -> 16 | C7: =IFERROR(IF(Inputs!$B$7+C6+1>=100,"",C6+1),"") -> 5 | D7: =IFERROR(IF(Inputs!$B$7+C7>=100,"",Inputs!$B$7+C7),"") -> 21 | E7: =IF(D7="","",INDEX(MORTALITY!$B:$B,MATCH(D7,MORTALITY!$A:$A,0))) -> 0.00251 | F7: =IF(D7="","",1-E7) -> 0.99749 | G7: =IF(D7="","",Inputs!$B$23) -> 0.025 | H7: =IF(D7="","",INDEX(Commutation!$L:$L,MATCH(Inputs!$B$7,Commutation!$A:$A,0))) -> 11.090171 | I7: =IF(D7="","",J6) -> 131.47573 | J7: =IF(D7>99,"",IF(E7=1,1000,MIN(1000,MAX(0,(INDEX(Commutation!$K:$K,MATCH(D8,Commutation!$A:$A,0))-(INDEX(Commutation!$K:$K,MATCH(Inputs!$B$7,Commutation!$A:$A,0))/((INDEX(Commutation!$H:$H,MATCH(Inputs!$B$7,Commutation!$A:$A,0))-INDEX(Commutation!$H:$H,MATCH(Inputs!$B$8,Commutation!$A:$A,0)))/INDEX(Commutation!$F:$F,MATCH(Inputs!$B$7,Commutation!$A:$A,0))))*MAX(0,(INDEX(Commutation!$H:$H,MATCH(D8,Commutation!$A:$A,0))-INDEX(Commutation!$H:$H,MATCH(Inputs!$B$8,Commutation!$A:$A,0)))/INDEX(Commutation!$F:$F,MATCH(D8,Commutation!$A:$A,0))))*1000)))) -> 159.79261 | K7: =IF(Inputs!$B$7+6-1>MAX(MORTALITY!$A:$A),"",IFERROR(J7,0)) -> 159.79261 | M7: =IF(A7="","",IF(E7=1,1000,IFERROR(((I7+IF(C7<=Inputs!$B$8,$H$2,0))*(1+G7)-E7*1000)/F7,0))) -> 143.98144
A8: =IF(D8>100,"",Inputs!$B$4) -> 34 | B8: =IF(D8>100,"",Inputs!$B$7) -> 16 | C8: =IFERROR(IF(Inputs!$B$7+C7+1>=100,"",C7+1),"") -> 6 | D8: =IFERROR(IF(Inputs!$B$7+C8>=100,"",Inputs!$B$7+C8),"") -> 22 | E8: =IF(D8="","",INDEX(MORTALITY!$B:$B,MATCH(D8,MORTALITY!$A:$A,0))) -> 0.00259 | F8: =IF(D8="","",1-E8) -> 0.99741 | G8: =IF(D8="","",Inputs!$B$23) -> 0.025 | H8: =IF(D8="","",INDEX(Commutation!$L:$L,MATCH(Inputs!$B$7,Commutation!$A:$A,0))) -> 11.090171 | I8: =IF(D8="","",J7) -> 159.79261 | J8: =IF(D8>99,"",IF(E8=1,1000,MIN(1000,MAX(0,(INDEX(Commutation!$K:$K,MATCH(D9,Commutation!$A:$A,0))-(INDEX(Commutation!$K:$K,MATCH(Inputs!$B$7,Commutation!$A:$A,0))/((INDEX(Commutation!$H:$H,MATCH(Inputs!$B$7,Commutation!$A:$A,0))-INDEX(Commutation!$H:$H,MATCH(Inputs!$B$8,Commutation!$A:$A,0)))/INDEX(Commutation!$F:$F,MATCH(Inputs!$B$7,Commutation!$A:$A,0))))*MAX(0,(INDEX(Commutation!$H:$H,MATCH(D9,Commutation!$A:$A,0))-INDEX(Commutation!$H:$H,MATCH(Inputs!$B$8,Commutation!$A:$A,0)))/INDEX(Commutation!$F:$F,MATCH(D9,Commutation!$A:$A,0))))*1000)))) -> 188.82539 | K8: =IF(Inputs!$B$7+7-1>MAX(MORTALITY!$A:$A),"",IFERROR(J8,0)) -> 188.82539 | M8: =IF(A8="","",IF(E8=1,1000,IFERROR(((I8+IF(C8<=Inputs!$B$8,$H$2,0))*(1+G8)-E8*1000)/F8,0))) -> 173.01295
A9: =IF(D9>100,"",Inputs!$B$4) -> 34 | B9: =IF(D9>100,"",Inputs!$B$7) -> 16 | C9: =IFERROR(IF(Inputs!$B$7+C8+1>=100,"",C8+1),"") -> 7 | D9: =IFERROR(IF(Inputs!$B$7+C9>=100,"",Inputs!$B$7+C9),"") -> 23 | E9: =IF(D9="","",INDEX(MORTALITY!$B:$B,MATCH(D9,MORTALITY!$A:$A,0))) -> 0.00268 | F9: =IF(D9="","",1-E9) -> 0.99732 | G9: =IF(D9="","",Inputs!$B$23) -> 0.025 | H9: =IF(D9="","",INDEX(Commutation!$L:$L,MATCH(Inputs!$B$7,Commutation!$A:$A,0))) -> 11.090171 | I9: =IF(D9="","",J8) -> 188.82539 | J9: =IF(D9>99,"",IF(E9=1,1000,MIN(1000,MAX(0,(INDEX(Commutation!$K:$K,MATCH(D10,Commutation!$A:$A,0))-(INDEX(Commutation!$K:$K,MATCH(Inputs!$B$7,Commutation!$A:$A,0))/((INDEX(Commutation!$H:$H,MATCH(Inputs!$B$7,Commutation!$A:$A,0))-INDEX(Commutation!$H:$H,MATCH(Inputs!$B$8,Commutation!$A:$A,0)))/INDEX(Commutation!$F:$F,MATCH(Inputs!$B$7,Commutation!$A:$A,0))))*MAX(0,(INDEX(Commutation!$H:$H,MATCH(D10,Commutation!$A:$A,0))-INDEX(Commutation!$H:$H,MATCH(Inputs!$B$8,Commutation!$A:$A,0)))/INDEX(Commutation!$F:$F,MATCH(D10,Commutation!$A:$A,0))))*1000)))) -> 218.59076 | K9: =IF(Inputs!$B$7+8-1>MAX(MORTALITY!$A:$A),"",IFERROR(J9,0)) -> 218.59076 | M9: =IF(A9="","",IF(E9=1,1000,IFERROR(((I9+IF(C9<=Inputs!$B$8,$H$2,0))*(1+G9)-E9*1000)/F9,0))) -> 202.77689
A10: =IF(D10>100,"",Inputs!$B$4) -> 34 | B10: =IF(D10>100,"",Inputs!$B$7) -> 16 | C10: =IFERROR(IF(Inputs!$B$7+C9+1>=100,"",C9+1),"") -> 8 | D10: =IFERROR(IF(Inputs!$B$7+C10>=100,"",Inputs!$B$7+C10),"") -> 24 | E10: =IF(D10="","",INDEX(MORTALITY!$B:$B,MATCH(D10,MORTALITY!$A:$A,0))) -> 0.00277 | F10: =IF(D10="","",1-E10) -> 0.99723 | G10: =IF(D10="","",Inputs!$B$23) -> 0.025 | H10: =IF(D10="","",INDEX(Commutation!$L:$L,MATCH(Inputs!$B$7,Commutation!$A:$A,0))) -> 11.090171 | I10: =IF(D10="","",J9) -> 218.59076 | J10: =IF(D10>99,"",IF(E10=1,1000,MIN(1000,MAX(0,(INDEX(Commutation!$K:$K,MATCH(D11,Commutation!$A:$A,0))-(INDEX(Commutation!$K:$K,MATCH(Inputs!$B$7,Commutation!$A:$A,0))/((INDEX(Commutation!$H:$H,MATCH(Inputs!$B$7,Commutation!$A:$A,0))-INDEX(Commutation!$H:$H,MATCH(Inputs!$B$8,Commutation!$A:$A,0)))/INDEX(Commutation!$F:$F,MATCH(Inputs!$B$7,Commutation!$A:$A,0))))*MAX(0,(INDEX(Commutation!$H:$H,MATCH(D11,Commutation!$A:$A,0))-INDEX(Commutation!$H:$H,MATCH(Inputs!$B$8,Commutation!$A:$A,0)))/INDEX(Commutation!$F:$F,MATCH(D11,Commutation!$A:$A,0))))*1000)))) -> 249.11449 | K10: =IF(Inputs!$B$7+9-1>MAX(MORTALITY!$A:$A),"",IFERROR(J10,0)) -> 249.11449 | M10: =IF(A10="","",IF(E10=1,1000,IFERROR(((I10+IF(C10<=Inputs!$B$8,$H$2,0))*(1+G10)-E10*1000)/F10,0))) -> 233.29919
A11: =IF(D11>100,"",Inputs!$B$4) -> 34 | B11: =IF(D11>100,"",Inputs!$B$7) -> 16 | C11: =IFERROR(IF(Inputs!$B$7+C10+1>=100,"",C10+1),"") -> 9 | D11: =IFERROR(IF(Inputs!$B$7+C11>=100,"",Inputs!$B$7+C11),"") -> 25 | E11: =IF(D11="","",INDEX(MORTALITY!$B:$B,MATCH(D11,MORTALITY!$A:$A,0))) -> 0.00288 | F11: =IF(D11="","",1-E11) -> 0.99712 | G11: =IF(D11="","",Inputs!$B$23) -> 0.025 | H11: =IF(D11="","",INDEX(Commutation!$L:$L,MATCH(Inputs!$B$7,Commutation!$A:$A,0))) -> 11.090171 | I11: =IF(D11="","",J10) -> 249.11449 | J11: =IF(D11>99,"",IF(E11=1,1000,MIN(1000,MAX(0,(INDEX(Commutation!$K:$K,MATCH(D12,Commutation!$A:$A,0))-(INDEX(Commutation!$K:$K,MATCH(Inputs!$B$7,Commutation!$A:$A,0))/((INDEX(Commutation!$H:$H,MATCH(Inputs!$B$7,Commutation!$A:$A,0))-INDEX(Commutation!$H:$H,MATCH(Inputs!$B$8,Commutation!$A:$A,0)))/INDEX(Commutation!$F:$F,MATCH(Inputs!$B$7,Commutation!$A:$A,0))))*MAX(0,(INDEX(Commutation!$H:$H,MATCH(D12,Commutation!$A:$A,0))-INDEX(Commutation!$H:$H,MATCH(Inputs!$B$8,Commutation!$A:$A,0)))/INDEX(Commutation!$F:$F,MATCH(D12,Commutation!$A:$A,0))))*1000)))) -> 280.40884 | K11: =IF(Inputs!$B$7+10-1>MAX(MORTALITY!$A:$A),"",IFERROR(J11,0)) -> 280.40884 | M11: =IF(A11="","",IF(E11=1,1000,IFERROR(((I11+IF(C11<=Inputs!$B$8,$H$2,0))*(1+G11)-E11*1000)/F11,0))) -> 264.5918
A12: =IF(D12>100,"",Inputs!$B$4) -> 34 | B12: =IF(D12>100,"",Inputs!$B$7) -> 16 | C12: =IFERROR(IF(Inputs!$B$7+C11+1>=100,"",C11+1),"") -> 10 | D12: =IFERROR(IF(Inputs!$B$7+C12>=100,"",Inputs!$B$7+C12),"") -> 26 | E12: =IF(D12="","",INDEX(MORTALITY!$B:$B,MATCH(D12,MORTALITY!$A:$A,0))) -> 0.00299 | F12: =IF(D12="","",1-E12) -> 0.99701 | G12: =IF(D12="","",Inputs!$B$23) -> 0.025 | H12: =IF(D12="","",INDEX(Commutation!$L:$L,MATCH(Inputs!$B$7,Commutation!$A:$A,0))) -> 11.090171 | I12: =IF(D12="","",J11) -> 280.40884 | J12: =IF(D12>99,"",IF(E12=1,1000,MIN(1000,MAX(0,(INDEX(Commutation!$K:$K,MATCH(D13,Commutation!$A:$A,0))-(INDEX(Commutation!$K:$K,MATCH(Inputs!$B$7,Commutation!$A:$A,0))/((INDEX(Commutation!$H:$H,MATCH(Inputs!$B$7,Commutation!$A:$A,0))-INDEX(Commutation!$H:$H,MATCH(Inputs!$B$8,Commutation!$A:$A,0)))/INDEX(Commutation!$F:$F,MATCH(Inputs!$B$7,Commutation!$A:$A,0))))*MAX(0,(INDEX(Commutation!$H:$H,MATCH(D13,Commutation!$A:$A,0))-INDEX(Commutation!$H:$H,MATCH(Inputs!$B$8,Commutation!$A:$A,0)))/INDEX(Commutation!$F:$F,MATCH(D13,Commutation!$A:$A,0))))*1000)))) -> 312.50235 | K12: =IF(Inputs!$B$7+11-1>MAX(MORTALITY!$A:$A),"",IFERROR(J12,0)) -> 312.50235 | M12: =IF(A12="","",IF(E12=1,1000,IFERROR(((I12+IF(C12<=Inputs!$B$8,$H$2,0))*(1+G12)-E12*1000)/F12,0))) -> 296.68357
A13: =IF(D13>100,"",Inputs!$B$4) -> 34 | B13: =IF(D13>100,"",Inputs!$B$7) -> 16 | C13: =IFERROR(IF(Inputs!$B$7+C12+1>=100,"",C12+1),"") -> 11 | D13: =IFERROR(IF(Inputs!$B$7+C13>=100,"",Inputs!$B$7+C13),"") -> 27 | E13: =IF(D13="","",INDEX(MORTALITY!$B:$B,MATCH(D13,MORTALITY!$A:$A,0))) -> 0.00311 | F13: =IF(D13="","",1-E13) -> 0.99689 | G13: =IF(D13="","",Inputs!$B$23) -> 0.025 | H13: =IF(D13="","",INDEX(Commutation!$L:$L,MATCH(Inputs!$B$7,Commutation!$A:$A,0))) -> 11.090171 | I13: =IF(D13="","",J12) -> 312.50235 | J13: =IF(D13>99,"",IF(E13=1,1000,MIN(1000,MAX(0,(INDEX(Commutation!$K:$K,MATCH(D14,Commutation!$A:$A,0))-(INDEX(Commutation!$K:$K,MATCH(Inputs!$B$7,Commutation!$A:$A,0))/((INDEX(Commutation!$H:$H,MATCH(Inputs!$B$7,Commutation!$A:$A,0))-INDEX(Commutation!$H:$H,MATCH(Inputs!$B$8,Commutation!$A:$A,0)))/INDEX(Commutation!$F:$F,MATCH(Inputs!$B$7,Commutation!$A:$A,0))))*MAX(0,(INDEX(Commutation!$H:$H,MATCH(D14,Commutation!$A:$A,0))-INDEX(Commutation!$H:$H,MATCH(Inputs!$B$8,Commutation!$A:$A,0)))/INDEX(Commutation!$F:$F,MATCH(D14,Commutation!$A:$A,0))))*1000)))) -> 345.41807 | K13: =IF(Inputs!$B$7+12-1>MAX(MORTALITY!$A:$A),"",IFERROR(J13,0)) -> 345.41807 | M13: =IF(A13="","",IF(E13=1,1000,IFERROR(((I13+IF(C13<=Inputs!$B$8,$H$2,0))*(1+G13)-E13*1000)/F13,0))) -> 329.59738
A14: =IF(D14>100,"",Inputs!$B$4) -> 34 | B14: =IF(D14>100,"",Inputs!$B$7) -> 16 | C14: =IFERROR(IF(Inputs!$B$7+C13+1>=100,"",C13+1),"") -> 12 | D14: =IFERROR(IF(Inputs!$B$7+C14>=100,"",Inputs!$B$7+C14),"") -> 28 | E14: =IF(D14="","",INDEX(MORTALITY!$B:$B,MATCH(D14,MORTALITY!$A:$A,0))) -> 0.00325 | F14: =IF(D14="","",1-E14) -> 0.99675 | G14: =IF(D14="","",Inputs!$B$23) -> 0.025 | H14: =IF(D14="","",INDEX(Commutation!$L:$L,MATCH(Inputs!$B$7,Commutation!$A:$A,0))) -> 11.090171 | I14: =IF(D14="","",J13) -> 345.41807 | J14: =IF(D14>99,"",IF(E14=1,1000,MIN(1000,MAX(0,(INDEX(Commutation!$K:$K,MATCH(D15,Commutation!$A:$A,0))-(INDEX(Commutation!$K:$K,MATCH(Inputs!$B$7,Commutation!$A:$A,0))/((INDEX(Commutation!$H:$H,MATCH(Inputs!$B$7,Commutation!$A:$A,0))-INDEX(Commutation!$H:$H,MATCH(Inputs!$B$8,Commutation!$A:$A,0)))/INDEX(Commutation!$F:$F,MATCH(Inputs!$B$7,Commutation!$A:$A,0))))*MAX(0,(INDEX(Commutation!$H:$H,MATCH(D15,Commutation!$A:$A,0))-INDEX(Commutation!$H:$H,MATCH(Inputs!$B$8,Commutation!$A:$A,0)))/INDEX(Commutation!$F:$F,MATCH(D15,Commutation!$A:$A,0))))*1000)))) -> 379.17475 | K14: =IF(Inputs!$B$7+13-1>MAX(MORTALITY!$A:$A),"",IFERROR(J14,0)) -> 379.17475 | M14: =IF(A14="","",IF(E14=1,1000,IFERROR(((I14+IF(C14<=Inputs!$B$8,$H$2,0))*(1+G14)-E14*1000)/F14,0))) -> 363.35184
A15: =IF(D15>100,"",Inputs!$B$4) -> 34 | B15: =IF(D15>100,"",Inputs!$B$7) -> 16 | C15: =IFERROR(IF(Inputs!$B$7+C14+1>=100,"",C14+1),"") -> 13 | D15: =IFERROR(IF(Inputs!$B$7+C15>=100,"",Inputs!$B$7+C15),"") -> 29 | E15: =IF(D15="","",INDEX(MORTALITY!$B:$B,MATCH(D15,MORTALITY!$A:$A,0))) -> 0.0034 | F15: =IF(D15="","",1-E15) -> 0.9966 | G15: =IF(D15="","",Inputs!$B$23) -> 0.025 | H15: =IF(D15="","",INDEX(Commutation!$L:$L,MATCH(Inputs!$B$7,Commutation!$A:$A,0))) -> 11.090171 | I15: =IF(D15="","",J14) -> 379.17475 | J15: =IF(D15>99,"",IF(E15=1,1000,MIN(1000,MAX(0,(INDEX(Commutation!$K:$K,MATCH(D16,Commutation!$A:$A,0))-(INDEX(Commutation!$K:$K,MATCH(Inputs!$B$7,Commutation!$A:$A,0))/((INDEX(Commutation!$H:$H,MATCH(Inputs!$B$7,Commutation!$A:$A,0))-INDEX(Commutation!$H:$H,MATCH(Inputs!$B$8,Commutation!$A:$A,0)))/INDEX(Commutation!$F:$F,MATCH(Inputs!$B$7,Commutation!$A:$A,0))))*MAX(0,(INDEX(Commutation!$H:$H,MATCH(D16,Commutation!$A:$A,0))-INDEX(Commutation!$H:$H,MATCH(Inputs!$B$8,Commutation!$A:$A,0)))/INDEX(Commutation!$F:$F,MATCH(D16,Commutation!$A:$A,0))))*1000)))) -> 413.79994 | K15: =IF(Inputs!$B$7+14-1>MAX(MORTALITY!$A:$A),"",IFERROR(J15,0)) -> 413.79994 | M15: =IF(A15="","",IF(E15=1,1000,IFERROR(((I15+IF(C15<=Inputs!$B$8,$H$2,0))*(1+G15)-E15*1000)/F15,0))) -> 397.97465
A16: =IF(D16>100,"",Inputs!$B$4) -> 34 | B16: =IF(D16>100,"",Inputs!$B$7) -> 16 | C16: =IFERROR(IF(Inputs!$B$7+C15+1>=100,"",C15+1),"") -> 14 | D16: =IFERROR(IF(Inputs!$B$7+C16>=100,"",Inputs!$B$7+C16),"") -> 30 | E16: =IF(D16="","",INDEX(MORTALITY!$B:$B,MATCH(D16,MORTALITY!$A:$A,0))) -> 0.00356 | F16: =IF(D16="","",1-E16) -> 0.99644 | G16: =IF(D16="","",Inputs!$B$23) -> 0.025 | H16: =IF(D16="","",INDEX(Commutation!$L:$L,MATCH(Inputs!$B$7,Commutation!$A:$A,0))) -> 11.090171 | I16: =IF(D16="","",J15) -> 413.79994 | J16: =IF(D16>99,"",IF(E16=1,1000,MIN(1000,MAX(0,(INDEX(Commutation!$K:$K,MATCH(D17,Commutation!$A:$A,0))-(INDEX(Commutation!$K:$K,MATCH(Inputs!$B$7,Commutation!$A:$A,0))/((INDEX(Commutation!$H:$H,MATCH(Inputs!$B$7,Commutation!$A:$A,0))-INDEX(Commutation!$H:$H,MATCH(Inputs!$B$8,Commutation!$A:$A,0)))/INDEX(Commutation!$F:$F,MATCH(Inputs!$B$7,Commutation!$A:$A,0))))*MAX(0,(INDEX(Commutation!$H:$H,MATCH(D17,Commutation!$A:$A,0))-INDEX(Commutation!$H:$H,MATCH(Inputs!$B$8,Commutation!$A:$A,0)))/INDEX(Commutation!$F:$F,MATCH(D17,Commutation!$A:$A,0))))*1000)))) -> 422.08757 | K16: =IF(Inputs!$B$7+15-1>MAX(MORTALITY!$A:$A),"",IFERROR(J16,0)) -> 422.08757 | M16: =IF(A16="","",IF(E16=1,1000,IFERROR(((I16+IF(C16<=Inputs!$B$8,$H$2,0))*(1+G16)-E16*1000)/F16,0))) -> 433.49561
A17: =IF(D17>100,"",Inputs!$B$4) -> 34 | B17: =IF(D17>100,"",Inputs!$B$7) -> 16 | C17: =IFERROR(IF(Inputs!$B$7+C16+1>=100,"",C16+1),"") -> 15 | D17: =IFERROR(IF(Inputs!$B$7+C17>=100,"",Inputs!$B$7+C17),"") -> 31 | E17: =IF(D17="","",INDEX(MORTALITY!$B:$B,MATCH(D17,MORTALITY!$A:$A,0))) -> 0.00373 | F17: =IF(D17="","",1-E17) -> 0.99627 | G17: =IF(D17="","",Inputs!$B$23) -> 0.025 | H17: =IF(D17="","",INDEX(Commutation!$L:$L,MATCH(Inputs!$B$7,Commutation!$A:$A,0))) -> 11.090171 | I17: =IF(D17="","",J16) -> 422.08757 | J17: =IF(D17>99,"",IF(E17=1,1000,MIN(1000,MAX(0,(INDEX(Commutation!$K:$K,MATCH(D18,Commutation!$A:$A,0))-(INDEX(Commutation!$K:$K,MATCH(Inputs!$B$7,Commutation!$A:$A,0))/((INDEX(Commutation!$H:$H,MATCH(Inputs!$B$7,Commutation!$A:$A,0))-INDEX(Commutation!$H:$H,MATCH(Inputs!$B$8,Commutation!$A:$A,0)))/INDEX(Commutation!$F:$F,MATCH(Inputs!$B$7,Commutation!$A:$A,0))))*MAX(0,(INDEX(Commutation!$H:$H,MATCH(D18,Commutation!$A:$A,0))-INDEX(Commutation!$H:$H,MATCH(Inputs!$B$8,Commutation!$A:$A,0)))/INDEX(Commutation!$F:$F,MATCH(D18,Commutation!$A:$A,0))))*1000)))) -> 430.51559 | K17: =IF(Inputs!$B$7+16-1>MAX(MORTALITY!$A:$A),"",IFERROR(J17,0)) -> 430.51559 | M17: =IF(A17="","",IF(E17=1,1000,IFERROR(((I17+IF(C17<=Inputs!$B$8,$H$2,0))*(1+G17)-E17*1000)/F17,0))) -> 441.92557
A18: =IF(D18>100,"",Inputs!$B$4) -> 34 | B18: =IF(D18>100,"",Inputs!$B$7) -> 16 | C18: =IFERROR(IF(Inputs!$B$7+C17+1>=100,"",C17+1),"") -> 16 | D18: =IFERROR(IF(Inputs!$B$7+C18>=100,"",Inputs!$B$7+C18),"") -> 32 | E18: =IF(D18="","",INDEX(MORTALITY!$B:$B,MATCH(D18,MORTALITY!$A:$A,0))) -> 0.00392 | F18: =IF(D18="","",1-E18) -> 0.99608 | G18: =IF(D18="","",Inputs!$B$23) -> 0.025 | H18: =IF(D18="","",INDEX(Commutation!$L:$L,MATCH(Inputs!$B$7,Commutation!$A:$A,0))) -> 11.090171 | I18: =IF(D18="","",J17) -> 430.51559 | J18: =IF(D18>99,"",IF(E18=1,1000,MIN(1000,MAX(0,(INDEX(Commutation!$K:$K,MATCH(D19,Commutation!$A:$A,0))-(INDEX(Commutation!$K:$K,MATCH(Inputs!$B$7,Commutation!$A:$A,0))/((INDEX(Commutation!$H:$H,MATCH(Inputs!$B$7,Commutation!$A:$A,0))-INDEX(Commutation!$H:$H,MATCH(Inputs!$B$8,Commutation!$A:$A,0)))/INDEX(Commutation!$F:$F,MATCH(Inputs!$B$7,Commutation!$A:$A,0))))*MAX(0,(INDEX(Commutation!$H:$H,MATCH(D19,Commutation!$A:$A,0))-INDEX(Commutation!$H:$H,MATCH(Inputs!$B$8,Commutation!$A:$A,0)))/INDEX(Commutation!$F:$F,MATCH(D19,Commutation!$A:$A,0))))*1000)))) -> 439.07967 | K18: =IF(Inputs!$B$7+17-1>MAX(MORTALITY!$A:$A),"",IFERROR(J18,0)) -> 439.07967 | M18: =IF(A18="","",IF(E18=1,1000,IFERROR(((I18+IF(C18<=Inputs!$B$8,$H$2,0))*(1+G18)-E18*1000)/F18,0))) -> 450.49183
A19: =IF(D19>100,"",Inputs!$B$4) -> 34 | B19: =IF(D19>100,"",Inputs!$B$7) -> 16 | C19: =IFERROR(IF(Inputs!$B$7+C18+1>=100,"",C18+1),"") -> 17 | D19: =IFERROR(IF(Inputs!$B$7+C19>=100,"",Inputs!$B$7+C19),"") -> 33 | E19: =IF(D19="","",INDEX(MORTALITY!$B:$B,MATCH(D19,MORTALITY!$A:$A,0))) -> 0.00412 | F19: =IF(D19="","",1-E19) -> 0.99588 | G19: =IF(D19="","",Inputs!$B$23) -> 0.025 | H19: =IF(D19="","",INDEX(Commutation!$L:$L,MATCH(Inputs!$B$7,Commutation!$A:$A,0))) -> 11.090171 | I19: =IF(D19="","",J18) -> 439.07967 | J19: =IF(D19>99,"",IF(E19=1,1000,MIN(1000,MAX(0,(INDEX(Commutation!$K:$K,MATCH(D20,Commutation!$A:$A,0))-(INDEX(Commutation!$K:$K,MATCH(Inputs!$B$7,Commutation!$A:$A,0))/((INDEX(Commutation!$H:$H,MATCH(Inputs!$B$7,Commutation!$A:$A,0))-INDEX(Commutation!$H:$H,MATCH(Inputs!$B$8,Commutation!$A:$A,0)))/INDEX(Commutation!$F:$F,MATCH(Inputs!$B$7,Commutation!$A:$A,0))))*MAX(0,(INDEX(Commutation!$H:$H,MATCH(D20,Commutation!$A:$A,0))-INDEX(Commutation!$H:$H,MATCH(Inputs!$B$8,Commutation!$A:$A,0)))/INDEX(Commutation!$F:$F,MATCH(D20,Commutation!$A:$A,0))))*1000)))) -> 447.78152 | K19: =IF(Inputs!$B$7+18-1>MAX(MORTALITY!$A:$A),"",IFERROR(J19,0)) -> 447.78152 | M19: =IF(A19="","",IF(E19=1,1000,IFERROR(((I19+IF(C19<=Inputs!$B$8,$H$2,0))*(1+G19)-E19*1000)/F19,0))) -> 459.19597
